Workbook

Sheet Dashboard
B2: AFFILIATE DASHBOARD
B3: Ringkasan otomatis dari sheet Data Affiliate. Seluruh angka di halaman ini adalah rumus, jangan diketik manual.
B5: RINGKASAN UTAMA
B6: Metrik | C6: Nilai | D6: Keterangan
B7: Total Affiliate Terdata | C7: =COUNTA('Data Affiliate'!$B$6:$B$205) -> 1 | D7: Jumlah baris yang sudah terisi nama.
B8: Total GMV Histori | C8: =SUM('Data Affiliate'!$F$6:$F$205) -> 45750000 | D8: Penjumlahan seluruh GMV histori affiliate.
B9: Rata-rata GMV per Affiliate | C9: =IF($C$7=0,0,$C$8/$C$7) -> 45750000 | D9: Total GMV dibagi jumlah affiliate terdata.
B10: GMV Histori Tertinggi | C10: =MAX('Data Affiliate'!$F$6:$F$205) -> 45750000 | D10: Nilai GMV terbesar dalam database.
B11: Affiliate dengan GMV Tertinggi | C11: =IFERROR(INDEX('Data Affiliate'!$B$6:$B$205,MATCH(MAX('Data Affiliate'!$F$6:$F$205),'Data Affiliate'!$F$6:$F$205,0)),"-") -> Rina Kartika | D11: Nama pemilik GMV tertinggi.
B12: Total Followers | C12: =SUM('Data Affiliate'!$H$6:$H$205) -> 128000 | D12: Total jangkauan followers seluruh affiliate.
B13: Rata-rata Followers | C13: =IF($C$7=0,0,$C$12/$C$7) -> 128000 | D13: Total followers dibagi jumlah affiliate terdata.
B14: Sudah Dikirim Produk | C14: =SUMPRODUCT(('Data Affiliate'!$G$6:$G$205<>"")*1) -> 1 | D14: Baris yang kolom Product yang Dikirim sudah terisi.
B15: Belum Dikirim Produk | C15: =MAX(0,$C$7-$C$14) -> 0 | D15: Affiliate terdata yang belum menerima kiriman produk.
B16: Belum Dihubungi | C16: =SUMPRODUCT(('Data Affiliate'!$B$6:$B$205<>"")*('Data Affiliate'!$E$6:$E$205="")) -> 0 | D16: Nama sudah ada tetapi channel komunikasi masih kosong.
B18: BREAKDOWN CHANNEL KOMUNIKASI
B19: Channel | C19: Jumlah Affiliate | D19: Total GMV Histori | E19: Rata-rata GMV | F19: Total Followers | G19: % Kontribusi GMV
B20: =Referensi!$A$4 -> WhatsApp | C20: =COUNTIFS('Data Affiliate'!$E$6:$E$205,$B20) -> 0 | D20: =SUMIFS('Data Affiliate'!$F$6:$F$205,'Data Affiliate'!$E$6:$E$205,$B20) -> 0 | E20: =IF($C20=0,0,$D20/$C20) -> 0 | F20: =SUMIFS('Data Affiliate'!$H$6:$H$205,'Data Affiliate'!$E$6:$E$205,$B20) -> 0 | G20: =IF($D$28=0,0,$D20/$D$28) -> 0
B21: =Referensi!$A$5 -> Instagram DM | C21: =COUNTIFS('Data Affiliate'!$E$6:$E$205,$B21) -> 1 | D21: =SUMIFS('Data Affiliate'!$F$6:$F$205,'Data Affiliate'!$E$6:$E$205,$B21) -> 45750000 | E21: =IF($C21=0,0,$D21/$C21) -> 45750000 | F21: =SUMIFS('Data Affiliate'!$H$6:$H$205,'Data Affiliate'!$E$6:$E$205,$B21) -> 128000 | G21: =IF($D$28=0,0,$D21/$D$28) -> 1
B22: =Referensi!$A$6 -> TikTok DM | C22: =COUNTIFS('Data Affiliate'!$E$6:$E$205,$B22) -> 0 | D22: =SUMIFS('Data Affiliate'!$F$6:$F$205,'Data Affiliate'!$E$6:$E$205,$B22) -> 0 | E22: =IF($C22=0,0,$D22/$C22) -> 0 | F22: =SUMIFS('Data Affiliate'!$H$6:$H$205,'Data Affiliate'!$E$6:$E$205,$B22) -> 0 | G22: =IF($D$28=0,0,$D22/$D$28) -> 0
B23: =Referensi!$A$7 -> Email | C23: =COUNTIFS('Data Affiliate'!$E$6:$E$205,$B23) -> 0 | D23: =SUMIFS('Data Affiliate'!$F$6:$F$205,'Data Affiliate'!$E$6:$E$205,$B23) -> 0 | E23: =IF($C23=0,0,$D23/$C23) -> 0 | F23: =SUMIFS('Data Affiliate'!$H$6:$H$205,'Data Affiliate'!$E$6:$E$205,$B23) -> 0 | G23: =IF($D$28=0,0,$D23/$D$28) -> 0
B24: =Referensi!$A$8 -> Telepon | C24: =COUNTIFS('Data Affiliate'!$E$6:$E$205,$B24) -> 0 | D24: =SUMIFS('Data Affiliate'!$F$6:$F$205,'Data Affiliate'!$E$6:$E$205,$B24) -> 0 | E24: =IF($C24=0,0,$D24/$C24) -> 0 | F24: =SUMIFS('Data Affiliate'!$H$6:$H$205,'Data Affiliate'!$E$6:$E$205,$B24) -> 0 | G24: =IF($D$28=0,0,$D24/$D$28) -> 0
B25: =Referensi!$A$9 -> Shopee Chat | C25: =COUNTIFS('Data Affiliate'!$E$6:$E$205,$B25) -> 0 | D25: =SUMIFS('Data Affiliate'!$F$6:$F$205,'Data Affiliate'!$E$6:$E$205,$B25) -> 0 | E25: =IF($C25=0,0,$D25/$C25) -> 0 | F25: =SUMIFS('Data Affiliate'!$H$6:$H$205,'Data Affiliate'!$E$6:$E$205,$B25) -> 0 | G25: =IF($D$28=0,0,$D25/$D$28) -> 0
B26: =Referensi!$A$10 -> Tokopedia Chat | C26: =COUNTIFS('Data Affiliate'!$E$6:$E$205,$B26) -> 0 | D26: =SUMIFS('Data Affiliate'!$F$6:$F$205,'Data Affiliate'!$E$6:$E$205,$B26) -> 0 | E26: =IF($C26=0,0,$D26/$C26) -> 0 | F26: =SUMIFS('Data Affiliate'!$H$6:$H$205,'Data Affiliate'!$E$6:$E$205,$B26) -> 0 | G26: =IF($D$28=0,0,$D26/$D$28) -> 0
B27: =Referensi!$A$11 -> Offline / Event | C27: =COUNTIFS('Data Affiliate'!$E$6:$E$205,$B27) -> 0 | D27: =SUMIFS('Data Affiliate'!$F$6:$F$205,'Data Affiliate'!$E$6:$E$205,$B27) -> 0 | E27: =IF($C27=0,0,$D27/$C27) -> 0 | F27: =SUMIFS('Data Affiliate'!$H$6:$H$205,'Data Affiliate'!$E$6:$E$205,$B27) -> 0 | G27: =IF($D$28=0,0,$D27/$D$28) -> 0
B28: TOTAL / TERISI | C28: =SUM($C$20:$C$27) -> 1 | D28: =SUM($D$20:$D$27) -> 45750000 | E28: =IF($C$28=0,0,$D$28/$C$28) -> 45750000 | F28: =SUM($F$20:$F$27) -> 128000 | G28: =IF($D$28=0,0,SUM($G$20:$G$27)) -> 1
B29: Catatan: baris yang kolom channelnya masih kosong tidak masuk hitungan tabel ini. Lihat metrik Belum Dihubungi di ringkasan utama.
B31: SEGMENTASI JUMLAH FOLLOWERS
B32: Tier | C32: Rentang Followers | D32: Jumlah Affiliate | E32: Total GMV Histori | F32: Rata-rata GMV | G32: % Kontribusi GMV
B33: =Referensi!$C$5 -> Nano | C33: =Referensi!$D$5 -> Di bawah 10.000 | D33: =COUNTIFS('Data Affiliate'!$H$6:$H$205,">="&Referensi!$E$5,'Data Affiliate'!$H$6:$H$205,"<="&Referensi!$F$5) -> 0 | E33: =SUMIFS('Data Affiliate'!$F$6:$F$205,'Data Affiliate'!$H$6:$H$205,">="&Referensi!$E$5,'Data Affiliate'!$H$6:$H$205,"<="&Referensi!$F$5) -> 0 | F33: =IF($D33=0,0,$E33/$D33) -> 0 | G33: =IF($E$38=0,0,$E33/$E$38) -> 0
B34: =Referensi!$C$6 -> Micro | C34: =Referensi!$D$6 -> 10.000 sampai 49.999 | D34: =COUNTIFS('Data Affiliate'!$H$6:$H$205,">="&Referensi!$E$6,'Data Affiliate'!$H$6:$H$205,"<="&Referensi!$F$6) -> 0 | E34: =SUMIFS('Data Affiliate'!$F$6:$F$205,'Data Affiliate'!$H$6:$H$205,">="&Referensi!$E$6,'Data Affiliate'!$H$6:$H$205,"<="&Referensi!$F$6) -> 0 | F34: =IF($D34=0,0,$E34/$D34) -> 0 | G34: =IF($E$38=0,0,$E34/$E$38) -> 0
B35: =Referensi!$C$7 -> Mid | C35: =Referensi!$D$7 -> 50.000 sampai 249.999 | D35: =COUNTIFS('Data Affiliate'!$H$6:$H$205,">="&Referensi!$E$7,'Data Affiliate'!$H$6:$H$205,"<="&Referensi!$F$7) -> 1 | E35: =SUMIFS('Data Affiliate'!$F$6:$F$205,'Data Affiliate'!$H$6:$H$205,">="&Referensi!$E$7,'Data Affiliate'!$H$6:$H$205,"<="&Referensi!$F$7) -> 45750000 | F35: =IF($D35=0,0,$E35/$D35) -> 45750000 | G35: =IF($E$38=0,0,$E35/$E$38) -> 1
B36: =Referensi!$C$8 -> Macro | C36: =Referensi!$D$8 -> 250.000 sampai 999.999 | D36: =COUNTIFS('Data Affiliate'!$H$6:$H$205,">="&Referensi!$E$8,'Data Affiliate'!$H$6:$H$205,"<="&Referensi!$F$8) -> 0 | E36: =SUMIFS('Data Affiliate'!$F$6:$F$205,'Data Affiliate'!$H$6:$H$205,">="&Referensi!$E$8,'Data Affiliate'!$H$6:$H$205,"<="&Referensi!$F$8) -> 0 | F36: =IF($D36=0,0,$E36/$D36) -> 0 | G36: =IF($E$38=0,0,$E36/$E$38) -> 0
B37: =Referensi!$C$9 -> Mega | C37: =Referensi!$D$9 -> 1.000.000 ke atas | D37: =COUNTIFS('Data Affiliate'!$H$6:$H$205,">="&Referensi!$E$9,'Data Affiliate'!$H$6:$H$205,"<="&Referensi!$F$9) -> 0 | E37: =SUMIFS('Data Affiliate'!$F$6:$F$205,'Data Affiliate'!$H$6:$H$205,">="&Referensi!$E$9,'Data Affiliate'!$H$6:$H$205,"<="&Referensi!$F$9) -> 0 | F37: =IF($D37=0,0,$E37/$D37) -> 0 | G37: =IF($E$38=0,0,$E37/$E$38) -> 0
B38: TOTAL | C38: Seluruh tier | D38: =SUM($D$33:$D$37) -> 1 | E38: =SUM($E$33:$E$37) -> 45750000 | F38: =IF($D$38=0,0,$E$38/$D$38) -> 45750000 | G38: =IF($E$38=0,0,SUM($G$33:$G$37)) -> 1
B39: Batas tiap tier diatur di sheet Referensi kolom E dan F, silakan ubah bila definisi tier berbeda.
B41: LEGENDA DAN CARA PAKAI
B42: Sel kuning | C42: Baris contoh di sheet Data Affiliate baris 6. Timpa dengan data asli Anda.
B43: Sel putih | C43: Sel input manual. Isi kolom B sampai H sheet Data Affiliate mulai baris 6 sampai 205.
B44: Sel abu-abu | C44: Kolom No pada sheet Data Affiliate. Berisi rumus penomoran otomatis, jangan diketik.
B45: Angka hijau | C45: Hasil rumus otomatis di sheet Dashboard dan angka yang menarik data dari sheet lain.
...

Sheet Data Affiliate
A1: DATABASE AFFILIATE
A2: Isi tabel di bawah ini. Semua ringkasan di sheet Dashboard terhitung otomatis dari data ini.
A3: Cara pakai: kolom B sampai H diisi manual mulai baris 6. Kolom A (No) berisi rumus otomatis, jangan diketik. Baris 6 adalah baris contoh, silakan timpa dengan data asli. Kapasitas tabel 200 baris (baris 6 sampai 205).
A5: No | B5: Nama | C5: Nama Akun | D5: Nomor Whatsapp | E5: Dihubungi Lewat Apa? | F5: GMV Histori (Rp) | G5: Product yang Dikirim | H5: Jumlah Followers
A6: =IF($B6<>"",ROW()-5,"") -> 1 | B6: Rina Kartika | C6: @rinakartika.id | D6: 081234567890 | E6: Instagram DM | F6: 45750000 | G6: Tote Bag Series A (2 pcs) | H6: 128000
A7: =IF($B7<>"",ROW()-5,"")
A8: =IF($B8<>"",ROW()-5,"")
A9: =IF($B9<>"",ROW()-5,"")
A10: =IF($B10<>"",ROW()-5,"")
A11: =IF($B11<>"",ROW()-5,"")
A12: =IF($B12<>"",ROW()-5,"")
A13: =IF($B13<>"",ROW()-5,"")
A14: =IF($B14<>"",ROW()-5,"")
A15: =IF($B15<>"",ROW()-5,"")
A16: =IF($B16<>"",ROW()-5,"")
A17: =IF($B17<>"",ROW()-5,"")
A18: =IF($B18<>"",ROW()-5,"")
... A205: =IF($B205<>"",ROW()-5,"")

Sheet Referensi
A1: REFERENSI DAN PENGATURAN
A3: Pilihan Channel Komunikasi | C3: Segmentasi Jumlah Followers
A4: WhatsApp | C4: Tier | D4: Keterangan Rentang | E4: Batas Bawah | F4: Batas Atas
A5: Instagram DM | C5: Nano | D5: Di bawah 10.000 | E5: 0 | F5: 9999
A6: TikTok DM | C6: Micro | D6: 10.000 sampai 49.999 | E6: 10000 | F6: 49999
A7: Email | C7: Mid | D7: 50.000 sampai 249.999 | E7: 50000 | F7: 249999
A8: Telepon | C8: Macro | D8: 250.000 sampai 999.999 | E8: 250000 | F8: 999999
A9: Shopee Chat | C9: Mega | D9: 1.000.000 ke atas | E9: 1000000 | F9: 999999999
A10: Tokopedia Chat
A11: Offline / Event | C11: Catatan: angka biru adalah nilai yang boleh diubah manual. Mengubah batas tier di sini otomatis memperbarui perhitungan di sheet Dashboard.
A13: Catatan: menambah atau mengganti nama channel di kolom A akan otomatis terbaca oleh dropdown dan oleh tabel breakdown di sheet Dashboard.
