Workbook

Sheet Executive Summary
A1: Sophie Martin Website Advertising: Executive Summary
A2: Period: 1 July to 8 September 2026 (70 calendar days, ads delivered on 67 of them). Source: Meta Ads Manager export, Sales-Website Jul - Sep.xlsx. Currency: IDR.
A4: Question 1: How much have we spent to promote the website in total?
A5: Total website promotion spend | B5: ='Objective Summary'!D8 -> 42838221
A6: Awareness campaigns (brand reach) | B6: ='Objective Summary'!D5 -> 13298375 | C6: ='Objective Summary'!E5 -> 0.31043248
A7: Traffic campaigns (website visits) | B7: ='Objective Summary'!D6 -> 16151104 | C7: ='Objective Summary'!E6 -> 0.37702555
A8: Sales campaigns (purchases) | B8: ='Objective Summary'!D7 -> 13388742 | C8: ='Objective Summary'!E7 -> 0.31254197
A9: Average spend per day | B9: =IFERROR(B5/'Campaign Summary'!E10,0) -> 639376.43
A11: Question 2: What is our cost to acquire one client (CAC)?
A12: Blended CAC (all spend / all purchases). Recommended headline. | B12: ='CAC Lenses'!E5 -> 345469.52
A13: Conversion CAC (Sales campaigns only) | B13: ='CAC Lenses'!E6 -> 110650.76
A14: Best engine CAC (Cold Start Broad campaign) | B14: ='CAC Lenses'!E7 -> 91950.017
A15: Brand and traffic investment per purchase (Blended minus Conversion) | B15: ='CAC Lenses'!E9 -> 234818.76
A17: Supporting results
A18: Website purchases (clients acquired) | B18: ='Objective Summary'!I8 -> 124
A19: Purchase revenue (Meta attributed) | B19: ='Objective Summary'!J8 -> 23276290
A20: Average order value | B20: =IFERROR(B19/B18,0) -> 187712.02
A21: Blended ROAS (revenue / all spend) | B21: ='Objective Summary'!N8 -> 0.54335333
A22: Sales campaign ROAS | B22: ='Objective Summary'!N7 -> 1.6983783
A23: People reached | B23: ='Objective Summary'!F8 -> 15824357
A24: Landing page views | B24: ='Objective Summary'!G8 -> 135976
A25: Adds to cart | B25: ='Objective Summary'!H8 -> 1837
A26: Cart to purchase rate | B26: =IFERROR(B18/B25,0) -> 0.067501361
A28: How to read the CAC numbers
A29: 1. Blended CAC is the honest, fully loaded answer: every rupiah spent on the website divided by every purchase. It is high because 69% of the budget went to Awareness and Traffic campaigns, which are not built to produce purchases directly.
A30: 2. Conversion CAC is what it actually costs the Sales campaigns to win a buyer. This is the number to use when deciding whether to scale acquisition budget.
A31: 3. The gap between the two is the price of building an audience. It is an investment, but today it is not yet paying back inside the attribution window: Traffic campaigns delivered 118,907 landing page views and only 3 attributed purchases.
A32: 4. Blended CAC is higher than the average order value. First purchases are acquired at a loss unless repeat purchases follow. Track customer lifetime value to know whether this is acceptable.
A33: 5. All figures use Meta attribution (7-day click or 1-day view). Purchases that Meta could not attribute, for example organic or direct visits, are not in this data, so true CAC is likely somewhat lower than reported here.

Sheet Raw Data
A1: Campaign name | B1: Ad set name | C1: Day | D1: Delivery status | E1: Delivery level | F1: Reach | G1: Impressions | H1: Attribution setting | I1: Amount spent (IDR) | J1: Landing page views | K1: Website purchases | L1: Website purchases conversion value | M1: Website adds to cart | N1: Website adds to cart conversion value | O1: Website purchase ROAS (return on ad spend) | P1: Reporting starts | Q1: Reporting ends | R1: Objective | S1: Month
A2: Awareness / Reach / CBO / AON | B2: Broad Fashion | C2: 2026-07-01 | D2: not_delivering | E2: adset | F2: 91782 | G2: 91782 | H2: 7-day click or 1-day view | I2: 117766 | P2: 2026-07-01 | Q2: 2026-07-01 | R2: =TRIM(LEFT(A2,FIND("/",A2)-1)) -> Awareness | S2: =LEFT(C2,7) -> 2026-07
A3: Awareness / Reach / CBO / AON | B3: Fashion Brand | C3: 2026-07-01 | D3: not_delivering | E3: adset | F3: 564 | G3: 569 | H3: 7-day click or 1-day view | I3: 726 | P3: 2026-07-01 | Q3: 2026-07-01 | R3: =TRIM(LEFT(A3,FIND("/",A3)-1)) -> Awareness | S3: =LEFT(C3,7) -> 2026-07
A4: Awareness / Reach / CBO / AON | B4: Life Style | C4: 2026-07-01 | D4: not_delivering | E4: adset | F4: 181221 | G4: 181221 | H4: 7-day click or 1-day view | I4: 229595 | P4: 2026-07-01 | Q4: 2026-07-01 | R4: =TRIM(LEFT(A4,FIND("/",A4)-1)) -> Awareness | S4: =LEFT(C4,7) -> 2026-07
A5: Awareness / Reach / CBO / AON | B5: Broad Fashion | C5: 2026-07-02 | D5: not_delivering | E5: adset | F5: 98734 | G5: 101496 | H5: 7-day click or 1-day view | I5: 118386 | P5: 2026-07-02 | Q5: 2026-07-02 | R5: =TRIM(LEFT(A5,FIND("/",A5)-1)) -> Awareness | S5: =LEFT(C5,7) -> 2026-07
A6: Awareness / Reach / CBO / AON | B6: Fashion Brand | C6: 2026-07-02 | D6: not_delivering | E6: adset | F6: 8415 | G6: 8415 | H6: 7-day click or 1-day view | I6: 9699 | P6: 2026-07-02 | Q6: 2026-07-02 | R6: =TRIM(LEFT(A6,FIND("/",A6)-1)) -> Awareness | S6: =LEFT(C6,7) -> 2026-07
A7: Awareness / Reach / CBO / AON | B7: Life Style | C7: 2026-07-02 | D7: not_delivering | E7: adset | F7: 134299 | G7: 134299 | H7: 7-day click or 1-day view | I7: 155802 | P7: 2026-07-02 | Q7: 2026-07-02 | R7: =TRIM(LEFT(A7,FIND("/",A7)-1)) -> Awareness | S7: =LEFT(C7,7) -> 2026-07
A8: Awareness / Reach / CBO / AON | B8: Broad Fashion | C8: 2026-07-03 | D8: not_delivering | E8: adset | F8: 54860 | G8: 55036 | H8: 7-day click or 1-day view | I8: 64062 | P8: 2026-07-03 | Q8: 2026-07-03 | R8: =TRIM(LEFT(A8,FIND("/",A8)-1)) -> Awareness | S8: =LEFT(C8,7) -> 2026-07
A9: Awareness / Reach / CBO / AON | B9: Fashion Brand | C9: 2026-07-03 | D9: not_delivering | E9: adset | F9: 1550 | G9: 1550 | H9: 7-day click or 1-day view | I9: 1809 | P9: 2026-07-03 | Q9: 2026-07-03 | R9: =TRIM(LEFT(A9,FIND("/",A9)-1)) -> Awareness | S9: =LEFT(C9,7) -> 2026-07
A10: Awareness / Reach / CBO / AON | B10: Life Style | C10: 2026-07-03 | D10: not_delivering | E10: adset | F10: 171083 | G10: 174177 | H10: 7-day click or 1-day view | I10: 202417 | P10: 2026-07-03 | Q10: 2026-07-03 | R10: =TRIM(LEFT(A10,FIND("/",A10)-1)) -> Awareness | S10: =LEFT(C10,7) -> 2026-07
A11: Awareness / Reach / CBO / AON | B11: Broad Fashion | C11: 2026-07-04 | D11: not_delivering | E11: adset | F11: 82728 | G11: 83280 | H11: 7-day click or 1-day view | I11: 98107 | P11: 2026-07-04 | Q11: 2026-07-04 | R11: =TRIM(LEFT(A11,FIND("/",A11)-1)) -> Awareness | S11: =LEFT(C11,7) -> 2026-07
A12: Awareness / Reach / CBO / AON | B12: Fashion Brand | C12: 2026-07-04 | D12: not_delivering | E12: adset | F12: 2950 | G12: 2955 | H12: 7-day click or 1-day view | I12: 3447 | P12: 2026-07-04 | Q12: 2026-07-04 | R12: =TRIM(LEFT(A12,FIND("/",A12)-1)) -> Awareness | S12: =LEFT(C12,7) -> 2026-07
A13: Awareness / Reach / CBO / AON | B13: Life Style | C13: 2026-07-04 | D13: not_delivering | E13: adset | F13: 140531 | G13: 142038 | H13: 7-day click or 1-day view | I13: 166442 | P13: 2026-07-04 | Q13: 2026-07-04 | R13: =TRIM(LEFT(A13,FIND("/",A13)-1)) -> Awareness | S13: =LEFT(C13,7) -> 2026-07
... A37: Awareness / Reach / CBO / AON | B37: Life Style | C37: 2026-07-12 | D37: not_delivering | E37: adset | F37: 86114 | G37: 86414 | H37: 7-day click or 1-day view | I37: 105413 | P37: 2026-07-12 | Q37: 2026-07-12 | R37: =TRIM(LEFT(A37,FIND("/",A37)-1)) -> Awareness | S37: =LEFT(C37,7) -> 2026-07
A38: Awareness / Reach / CBO / SophieMartin | B38: AW-1 / Broad Cold Audience | C38: 2026-07-16 | D38: active | E38: adset | F38: 61449 | G38: 61449 | H38: 7-day click or 1-day view | I38: 71151 | J38: 8 | P38: 2026-07-16 | Q38: 2026-07-16 | R38: =TRIM(LEFT(A38,FIND("/",A38)-1)) -> Awareness | S38: =LEFT(C38,7) -> 2026-07
A39: Awareness / Reach / CBO / SophieMartin | B39: AW-2 / Interest - Fashion & Style | C39: 2026-07-16 | D39: active | E39: adset | F39: 78328 | G39: 78328 | H39: 7-day click or 1-day view | I39: 90846 | J39: 9 | P39: 2026-07-16 | Q39: 2026-07-16 | R39: =TRIM(LEFT(A39,FIND("/",A39)-1)) -> Awareness | S39: =LEFT(C39,7) -> 2026-07
A40: Awareness / Reach / CBO / SophieMartin | B40: AW-3 / Lookalike 3-5% (Engagers) | C40: 2026-07-16 | D40: active | E40: adset | F40: 4675 | G40: 4735 | H40: 7-day click or 1-day view | I40: 5477 | J40: 2 | P40: 2026-07-16 | Q40: 2026-07-16 | R40: =TRIM(LEFT(A40,FIND("/",A40)-1)) -> Awareness | S40: =LEFT(C40,7) -> 2026-07
A41: Awareness / Reach / CBO / SophieMartin | B41: AW-1 / Broad Cold Audience | C41: 2026-07-17 | D41: active | E41: adset | F41: 29340 | G41: 30125 | H41: 7-day click or 1-day view | I41: 35299 | J41: 3 | P41: 2026-07-17 | Q41: 2026-07-17 | R41: =TRIM(LEFT(A41,FIND("/",A41)-1)) -> Awareness | S41: =LEFT(C41,7) -> 2026-07
A42: Awareness / Reach / CBO / SophieMartin | B42: AW-2 / Interest - Fashion & Style | C42: 2026-07-17 | D42: active | E42: adset | F42: 122910 | G42: 125056 | H42: 7-day click or 1-day view | I42: 148108 | J42: 20 | P42: 2026-07-17 | Q42: 2026-07-17 | R42: =TRIM(LEFT(A42,FIND("/",A42)-1)) -> Awareness | S42: =LEFT(C42,7) -> 2026-07
A43: Awareness / Reach / CBO / SophieMartin | B43: AW-3 / Lookalike 3-5% (Engagers) | C43: 2026-07-17 | D43: active | E43: adset | F43: 1988 | G43: 2044 | H43: 7-day click or 1-day view | I43: 2421 | P43: 2026-07-17 | Q43: 2026-07-17 | R43: =TRIM(LEFT(A43,FIND("/",A43)-1)) -> Awareness | S43: =LEFT(C43,7) -> 2026-07
A44: Sales / Purchase / CBO / ColdStart Broad / SophieMartin / Jul26 | B44: ADS / Broad Advantage+ / Wanita 18-45 / ID / Feed-Story-Reels | C44: 2026-07-17 | D44: active | E44: adset | F44: 2424 | G44: 2555 | H44: 7-day click or 1-day view | I44: 32562 | J44: 40 | K44: 1 | L44: 201868 | M44: 6 | N44: 1044453 | O44: 6.1994964 | P44: 2026-07-17 | Q44: 2026-07-17 | R44: =TRIM(LEFT(A44,FIND("/",A44)-1)) -> Sales | S44: =LEFT(C44,7) -> 2026-07
A45: Traffic / LPV / Web / SophieMartin | B45: CL-1 Online Shopper Behaviour | C45: 2026-07-17 | D45: active | E45: adset | F45: 66691 | G45: 73213 | H45: 7-day click or 1-day view | I45: 247982 | J45: 1171 | M45: 1 | N45: 142672 | P45: 2026-07-17 | Q45: 2026-07-17 | R45: =TRIM(LEFT(A45,FIND("/",A45)-1)) -> Traffic | S45: =LEFT(C45,7) -> 2026-07
A46: Traffic / LPV / Web / SophieMartin | B46: CL-2 Video Viewers Retarget | C46: 2026-07-17 | D46: active | E46: adset | F46: 372 | G46: 398 | H46: 7-day click or 1-day view | I46: 1558 | J46: 11 | P46: 2026-07-17 | Q46: 2026-07-17 | R46: =TRIM(LEFT(A46,FIND("/",A46)-1)) -> Traffic | S46: =LEFT(C46,7) -> 2026-07
A47: Awareness / Reach / CBO / SophieMartin | B47: AW-1 / Broad Cold Audience | C47: 2026-07-18 | D47: active | E47: adset | F47: 149086 | G47: 150948 | H47: 7-day click or 1-day view | I47: 195034 | J47: 21 | P47: 2026-07-18 | Q47: 2026-07-18 | R47: =TRIM(LEFT(A47,FIND("/",A47)-1)) -> Awareness | S47: =LEFT(C47,7) -> 2026-07
A48: Awareness / Reach / CBO / SophieMartin | B48: AW-2 / Interest - Fashion & Style | C48: 2026-07-18 | D48: active | E48: adset | F48: 172360 | G48: 172360 | H48: 7-day click or 1-day view | I48: 222996 | J48: 37 | P48: 2026-07-18 | Q48: 2026-07-18 | R48: =TRIM(LEFT(A48,FIND("/",A48)-1)) -> Awareness | S48: =LEFT(C48,7) -> 2026-07
A49: Awareness / Reach / CBO / SophieMartin | B49: AW-3 / Lookalike 3-5% (Engagers) | C49: 2026-07-18 | D49: active | E49: adset | F49: 4763 | G49: 4791 | H49: 7-day click or 1-day view | I49: 6227 | P49: 2026-07-18 | Q49: 2026-07-18 | R49: =TRIM(LEFT(A49,FIND("/",A49)-1)) -> Awareness | S49: =LEFT(C49,7) -> 2026-07
A50: Sales / Purchase / CBO / ColdStart Broad / SophieMartin / Jul26 | B50: ADS / Broad Advantage+ / Wanita 18-45 / ID / Feed-Story-Reels | C50: 2026-07-18 | D50: active | E50: adset | F50: 8399 | G50: 9728 | H50: 7-day click or 1-day view | I50: 205990 | J50: 158 | K50: 1 | L50: 172868 | M50: 29 | N50: 4923984 | O50: 0.83920579 | P50: 2026-07-18 | Q50: 2026-07-18 | R50: =TRIM(LEFT(A50,FIND("/",A50)-1)) -> Sales | S50: =LEFT(C50,7) -> 2026-07
A51: Traffic / LPV / Web / SophieMartin | B51: CL-1 Online Shopper Behaviour | C51: 2026-07-18 | D51: active | E51: adset | F51: 57112 | G51: 69682 | H51: 7-day click or 1-day view | I51: 229087 | J51: 1600 | M51: 3 | N51: 450408 | P51: 2026-07-18 | Q51: 2026-07-18 | R51: =TRIM(LEFT(A51,FIND("/",A51)-1)) -> Traffic | S51: =LEFT(C51,7) -> 2026-07
A52: Traffic / LPV / Web / SophieMartin | B52: CL-2 Video Viewers Retarget | C52: 2026-07-18 | D52: active | E52: adset | F52: 175 | G52: 191 | H52: 7-day click or 1-day view | I52: 852 | J52: 10 | P52: 2026-07-18 | Q52: 2026-07-18 | R52: =TRIM(LEFT(A52,FIND("/",A52)-1)) -> Traffic | S52: =LEFT(C52,7) -> 2026-07
A53: Traffic / LPV / Web / SophieMartin | B53: CL-3 Lookalike 1-3% (Web Visitors) | C53: 2026-07-18 | D53: active | E53: adset | F53: 1312 | G53: 1366 | H53: 7-day click or 1-day view | I53: 5687 | J53: 46 | P53: 2026-07-18 | Q53: 2026-07-18 | R53: =TRIM(LEFT(A53,FIND("/",A53)-1)) -> Traffic | S53: =LEFT(C53,7) -> 2026-07
A54: Awareness / Reach / CBO / SophieMartin | B54: AW-1 / Broad Cold Audience | C54: 2026-07-19 | D54: active | E54: adset | F54: 124882 | G54: 126429 | H54: 7-day click or 1-day view | I54: 166945 | J54: 12 | P54: 2026-07-19 | Q54: 2026-07-19 | R54: =TRIM(LEFT(A54,FIND("/",A54)-1)) -> Awareness | S54: =LEFT(C54,7) -> 2026-07
A55: Awareness / Reach / CBO / SophieMartin | B55: AW-2 / Interest - Fashion & Style | C55: 2026-07-19 | D55: active | E55: adset | F55: 54748 | G55: 54980 | H55: 7-day click or 1-day view | I55: 72444 | J55: 7 | P55: 2026-07-19 | Q55: 2026-07-19 | R55: =TRIM(LEFT(A55,FIND("/",A55)-1)) -> Awareness | S55: =LEFT(C55,7) -> 2026-07
A56: Awareness / Reach / CBO / SophieMartin | B56: AW-3 / Lookalike 3-5% (Engagers) | C56: 2026-07-19 | D56: active | E56: adset | F56: 4359 | G56: 4395 | H56: 7-day click or 1-day view | I56: 5800 | P56: 2026-07-19 | Q56: 2026-07-19 | R56: =TRIM(LEFT(A56,FIND("/",A56)-1)) -> Awareness | S56: =LEFT(C56,7) -> 2026-07
A57: Sales / Purchase / CBO / ColdStart Broad / SophieMartin / Jul26 | B57: ADS / Broad Advantage+ / Wanita 18-45 / ID / Feed-Story-Reels | C57: 2026-07-19 | D57: active | E57: adset | F57: 11805 | G57: 15306 | H57: 7-day click or 1-day view | I57: 319273 | J57: 339 | K57: 3 | L57: 698590 | M57: 47 | N57: 7880260 | O57: 2.1880648 | P57: 2026-07-19 | Q57: 2026-07-19 | R57: =TRIM(LEFT(A57,FIND("/",A57)-1)) -> Sales | S57: =LEFT(C57,7) -> 2026-07
A58: Traffic / LPV / Web / SophieMartin | B58: CL-1 Online Shopper Behaviour | C58: 2026-07-19 | D58: active | E58: adset | F58: 87435 | G58: 117364 | H58: 7-day click or 1-day view | I58: 311941 | J58: 2307 | M58: 3 | N58: 553530 | P58: 2026-07-19 | Q58: 2026-07-19 | R58: =TRIM(LEFT(A58,FIND("/",A58)-1)) -> Traffic | S58: =LEFT(C58,7) -> 2026-07
A59: Traffic / LPV / Web / SophieMartin | B59: CL-2 Video Viewers Retarget | C59: 2026-07-19 | D59: active | E59: adset | F59: 305 | G59: 323 | H59: 7-day click or 1-day view | I59: 1207 | J59: 6 | P59: 2026-07-19 | Q59: 2026-07-19 | R59: =TRIM(LEFT(A59,FIND("/",A59)-1)) -> Traffic | S59: =LEFT(C59,7) -> 2026-07
A60: Traffic / LPV / Web / SophieMartin | B60: CL-3 Lookalike 1-3% (Web Visitors) | C60: 2026-07-19 | D60: active | E60: adset | F60: 1725 | G60: 1905 | H60: 7-day click or 1-day view | I60: 5753 | J60: 57 | P60: 2026-07-19 | Q60: 2026-07-19 | R60: =TRIM(LEFT(A60,FIND("/",A60)-1)) -> Traffic | S60: =LEFT(C60,7) -> 2026-07
A61: Awareness / Reach / CBO / SophieMartin | B61: AW-1 / Broad Cold Audience | C61: 2026-07-20 | D61: active | E61: adset | F61: 159595 | G61: 159595 | H61: 7-day click or 1-day view | I61: 200802 | J61: 39 | P61: 2026-07-20 | Q61: 2026-07-20 | R61: =TRIM(LEFT(A61,FIND("/",A61)-1)) -> Awareness | S61: =LEFT(C61,7) -> 2026-07
A62: Awareness / Reach / CBO / SophieMartin | B62: AW-2 / Interest - Fashion & Style | C62: 2026-07-20 | D62: active | E62: adset | F62: 28129 | G62: 28129 | H62: 7-day click or 1-day view | I62: 35274 | J62: 6 | P62: 2026-07-20 | Q62: 2026-07-20 | R62: =TRIM(LEFT(A62,FIND("/",A62)-1)) -> Awareness | S62: =LEFT(C62,7) -> 2026-07
A63: Awareness / Reach / CBO / SophieMartin | B63: AW-3 / Lookalike 3-5% (Engagers) | C63: 2026-07-20 | D63: active | E63: adset | F63: 24014 | G63: 24205 | H63: 7-day click or 1-day view | I63: 30526 | J63: 8 | P63: 2026-07-20 | Q63: 2026-07-20 | R63: =TRIM(LEFT(A63,FIND("/",A63)-1)) -> Awareness | S63: =LEFT(C63,7) -> 2026-07
...

Sheet Campaign Summary
A1: Campaign Summary (1 Jul to 8 Sep 2026)
A2: All values are SUMIFS formulas over the Raw Data sheet. Attribution: 7-day click or 1-day view, as reported by Meta Ads Manager.
A4: Objective | B4: Campaign name | C4: First day | D4: Last day | E4: Days active | F4: Spend (IDR) | G4: Reach | H4: Impressions | I4: Landing page views | J4: Adds to cart | K4: Purchases | L4: Revenue (IDR) | M4: Share of spend | N4: CPM (IDR) | O4: Cost per LPV (IDR) | P4: Cost per ATC (IDR) | Q4: CAC (IDR) | R4: ROAS
A5: Awareness | B5: Awareness / Reach / CBO / AON | C5: 2026-07-01 | D5: 2026-07-12 | E5: 12 | F5: =SUMIFS('Raw Data'!$I:$I,'Raw Data'!$A:$A,$B5) -> 3417371 | G5: =SUMIFS('Raw Data'!$F:$F,'Raw Data'!$A:$A,$B5) -> 2831623 | H5: =SUMIFS('Raw Data'!$G:$G,'Raw Data'!$A:$A,$B5) -> 2863453 | I5: =SUMIFS('Raw Data'!$J:$J,'Raw Data'!$A:$A,$B5) -> 0 | J5: =SUMIFS('Raw Data'!$M:$M,'Raw Data'!$A:$A,$B5) -> 0 | K5: =SUMIFS('Raw Data'!$K:$K,'Raw Data'!$A:$A,$B5) -> 0 | L5: =SUMIFS('Raw Data'!$L:$L,'Raw Data'!$A:$A,$B5) -> 0 | M5: =IFERROR(F5/$F$10,0) -> 0.079773878 | N5: =IFERROR(F5/H5*1000,0) -> 1193.4441 | O5: =IFERROR(F5/I5,0) -> 0 | P5: =IFERROR(F5/J5,0) -> 0 | Q5: =IFERROR(F5/K5,0) -> 0 | R5: =IFERROR(L5/F5,0) -> 0
A6: Awareness | B6: Awareness / Reach / CBO / SophieMartin | C6: 2026-07-16 | D6: 2026-09-08 | E6: 55 | F6: =SUMIFS('Raw Data'!$I:$I,'Raw Data'!$A:$A,$B6) -> 9881004 | G6: =SUMIFS('Raw Data'!$F:$F,'Raw Data'!$A:$A,$B6) -> 7637296 | H6: =SUMIFS('Raw Data'!$G:$G,'Raw Data'!$A:$A,$B6) -> 7697821 | I6: =SUMIFS('Raw Data'!$J:$J,'Raw Data'!$A:$A,$B6) -> 1396 | J6: =SUMIFS('Raw Data'!$M:$M,'Raw Data'!$A:$A,$B6) -> 6 | K6: =SUMIFS('Raw Data'!$K:$K,'Raw Data'!$A:$A,$B6) -> 0 | L6: =SUMIFS('Raw Data'!$L:$L,'Raw Data'!$A:$A,$B6) -> 0 | M6: =IFERROR(F6/$F$10,0) -> 0.2306586 | N6: =IFERROR(F6/H6*1000,0) -> 1283.6105 | O6: =IFERROR(F6/I6,0) -> 7078.0831 | P6: =IFERROR(F6/J6,0) -> 1646834 | Q6: =IFERROR(F6/K6,0) -> 0 | R6: =IFERROR(L6/F6,0) -> 0
A7: Traffic | B7: Traffic / LPV / Web / SophieMartin | C7: 2026-07-17 | D7: 2026-09-08 | E7: 54 | F7: =SUMIFS('Raw Data'!$I:$I,'Raw Data'!$A:$A,$B7) -> 16151104 | G7: =SUMIFS('Raw Data'!$F:$F,'Raw Data'!$A:$A,$B7) -> 4757233 | H7: =SUMIFS('Raw Data'!$G:$G,'Raw Data'!$A:$A,$B7) -> 5774068 | I7: =SUMIFS('Raw Data'!$J:$J,'Raw Data'!$A:$A,$B7) -> 118907 | J7: =SUMIFS('Raw Data'!$M:$M,'Raw Data'!$A:$A,$B7) -> 332 | K7: =SUMIFS('Raw Data'!$K:$K,'Raw Data'!$A:$A,$B7) -> 3 | L7: =SUMIFS('Raw Data'!$L:$L,'Raw Data'!$A:$A,$B7) -> 537141 | M7: =IFERROR(F7/$F$10,0) -> 0.37702555 | N7: =IFERROR(F7/H7*1000,0) -> 2797.1794 | O7: =IFERROR(F7/I7,0) -> 135.82972 | P7: =IFERROR(F7/J7,0) -> 48647.904 | Q7: =IFERROR(F7/K7,0) -> 5383701.3 | R7: =IFERROR(L7/F7,0) -> 0.033257231
A8: Sales | B8: Sales / Purchase / CBO / ColdStart Broad / SophieMartin / Jul26 | C8: 2026-07-17 | D8: 2026-09-08 | E8: 54 | F8: =SUMIFS('Raw Data'!$I:$I,'Raw Data'!$A:$A,$B8) -> 10666202 | G8: =SUMIFS('Raw Data'!$F:$F,'Raw Data'!$A:$A,$B8) -> 499852 | H8: =SUMIFS('Raw Data'!$G:$G,'Raw Data'!$A:$A,$B8) -> 583832 | I8: =SUMIFS('Raw Data'!$J:$J,'Raw Data'!$A:$A,$B8) -> 13399 | J8: =SUMIFS('Raw Data'!$M:$M,'Raw Data'!$A:$A,$B8) -> 1374 | K8: =SUMIFS('Raw Data'!$K:$K,'Raw Data'!$A:$A,$B8) -> 116 | L8: =SUMIFS('Raw Data'!$L:$L,'Raw Data'!$A:$A,$B8) -> 21756098 | M8: =IFERROR(F8/$F$10,0) -> 0.24898798 | N8: =IFERROR(F8/H8*1000,0) -> 18269.3 | O8: =IFERROR(F8/I8,0) -> 796.04463 | P8: =IFERROR(F8/J8,0) -> 7762.8836 | Q8: =IFERROR(F8/K8,0) -> 91950.017 | R8: =IFERROR(L8/F8,0) -> 2.039723
A9: Sales | B9: Sales / Retargeting / CBO / SophieMartin | C9: 2026-07-31 | D9: 2026-08-18 | E9: 19 | F9: =SUMIFS('Raw Data'!$I:$I,'Raw Data'!$A:$A,$B9) -> 2722540 | G9: =SUMIFS('Raw Data'!$F:$F,'Raw Data'!$A:$A,$B9) -> 98353 | H9: =SUMIFS('Raw Data'!$G:$G,'Raw Data'!$A:$A,$B9) -> 167525 | I9: =SUMIFS('Raw Data'!$J:$J,'Raw Data'!$A:$A,$B9) -> 2274 | J9: =SUMIFS('Raw Data'!$M:$M,'Raw Data'!$A:$A,$B9) -> 125 | K9: =SUMIFS('Raw Data'!$K:$K,'Raw Data'!$A:$A,$B9) -> 5 | L9: =SUMIFS('Raw Data'!$L:$L,'Raw Data'!$A:$A,$B9) -> 983051 | M9: =IFERROR(F9/$F$10,0) -> 0.063553993 | N9: =IFERROR(F9/H9*1000,0) -> 16251.545 | O9: =IFERROR(F9/I9,0) -> 1197.2471 | P9: =IFERROR(F9/J9,0) -> 21780.32 | Q9: =IFERROR(F9/K9,0) -> 544508 | R9: =IFERROR(L9/F9,0) -> 0.36107863
A10: Total | B10: All campaigns | E10: =SUMPRODUCT(1/COUNTIF('Raw Data'!$C$2:$C$459,'Raw Data'!$C$2:$C$459)) -> 67 | F10: =SUM(F5:F9) -> 42838221 | G10: =SUM(G5:G9) -> 15824357 | H10: =SUM(H5:H9) -> 17086699 | I10: =SUM(I5:I9) -> 135976 | J10: =SUM(J5:J9) -> 1837 | K10: =SUM(K5:K9) -> 124 | L10: =SUM(L5:L9) -> 23276290 | M10: =SUM(M5:M9) -> 1 | N10: =IFERROR(F10/H10*1000,0) -> 2507.1092 | O10: =IFERROR(F10/I10,0) -> 315.04251 | P10: =IFERROR(F10/J10,0) -> 23319.663 | Q10: =IFERROR(F10/K10,0) -> 345469.52 | R10: =IFERROR(L10/F10,0) -> 0.54335333
A12: Note: "Awareness / Reach / CBO / AON" ran 1 to 12 July only and is included in total spend. Confirm with the ads team whether this campaign belongs to the Sophie Martin website budget; if not, remove it from the Raw Data sheet and every total updates automatically.

Sheet Objective Summary
A1: Spend and results by campaign objective
A2: Each objective plays a different role in the funnel. Only Sales campaigns are optimised for purchases, so CAC is only a fair metric for that layer.
A4: Objective | B4: Funnel role | C4: Primary success metric | D4: Spend (IDR) | E4: Share of spend | F4: Reach | G4: Landing page views | H4: Adds to cart | I4: Purchases | J4: Revenue (IDR) | K4: CPM (IDR) | L4: Cost per LPV (IDR) | M4: CAC (IDR) | N4: ROAS
A5: Awareness | B5: Top of funnel: build brand recall | C5: Reach and CPM | D5: =SUMIFS('Raw Data'!$I:$I,'Raw Data'!$R:$R,$A5) -> 13298375 | E5: =IFERROR(D5/$D$8,0) -> 0.31043248 | F5: =SUMIFS('Raw Data'!$F:$F,'Raw Data'!$R:$R,$A5) -> 10468919 | G5: =SUMIFS('Raw Data'!$J:$J,'Raw Data'!$R:$R,$A5) -> 1396 | H5: =SUMIFS('Raw Data'!$M:$M,'Raw Data'!$R:$R,$A5) -> 6 | I5: =SUMIFS('Raw Data'!$K:$K,'Raw Data'!$R:$R,$A5) -> 0 | J5: =SUMIFS('Raw Data'!$L:$L,'Raw Data'!$R:$R,$A5) -> 0 | K5: =IFERROR(D5/SUMIFS('Raw Data'!$G:$G,'Raw Data'!$R:$R,$A5)*1000,0) -> 1259.1639 | L5: =IFERROR(D5/G5,0) -> 9526.0566 | M5: =IFERROR(D5/I5,0) -> 0 | N5: =IFERROR(J5/D5,0) -> 0
A6: Traffic | B6: Middle of funnel: bring shoppers to the website | C6: Landing page views and cost per LPV | D6: =SUMIFS('Raw Data'!$I:$I,'Raw Data'!$R:$R,$A6) -> 16151104 | E6: =IFERROR(D6/$D$8,0) -> 0.37702555 | F6: =SUMIFS('Raw Data'!$F:$F,'Raw Data'!$R:$R,$A6) -> 4757233 | G6: =SUMIFS('Raw Data'!$J:$J,'Raw Data'!$R:$R,$A6) -> 118907 | H6: =SUMIFS('Raw Data'!$M:$M,'Raw Data'!$R:$R,$A6) -> 332 | I6: =SUMIFS('Raw Data'!$K:$K,'Raw Data'!$R:$R,$A6) -> 3 | J6: =SUMIFS('Raw Data'!$L:$L,'Raw Data'!$R:$R,$A6) -> 537141 | K6: =IFERROR(D6/SUMIFS('Raw Data'!$G:$G,'Raw Data'!$R:$R,$A6)*1000,0) -> 2797.1794 | L6: =IFERROR(D6/G6,0) -> 135.82972 | M6: =IFERROR(D6/I6,0) -> 5383701.3 | N6: =IFERROR(J6/D6,0) -> 0.033257231
A7: Sales | B7: Bottom of funnel: convert shoppers into buyers | C7: Purchases, CAC and ROAS | D7: =SUMIFS('Raw Data'!$I:$I,'Raw Data'!$R:$R,$A7) -> 13388742 | E7: =IFERROR(D7/$D$8,0) -> 0.31254197 | F7: =SUMIFS('Raw Data'!$F:$F,'Raw Data'!$R:$R,$A7) -> 598205 | G7: =SUMIFS('Raw Data'!$J:$J,'Raw Data'!$R:$R,$A7) -> 15673 | H7: =SUMIFS('Raw Data'!$M:$M,'Raw Data'!$R:$R,$A7) -> 1499 | I7: =SUMIFS('Raw Data'!$K:$K,'Raw Data'!$R:$R,$A7) -> 121 | J7: =SUMIFS('Raw Data'!$L:$L,'Raw Data'!$R:$R,$A7) -> 22739149 | K7: =IFERROR(D7/SUMIFS('Raw Data'!$G:$G,'Raw Data'!$R:$R,$A7)*1000,0) -> 17819.415 | L7: =IFERROR(D7/G7,0) -> 854.25522 | M7: =IFERROR(D7/I7,0) -> 110650.76 | N7: =IFERROR(J7/D7,0) -> 1.6983783
A8: Total | B8: All website promotion | C8: Blended CAC and blended ROAS | D8: =SUM(D5:D7) -> 42838221 | E8: =SUM(E5:E7) -> 1 | F8: =SUM(F5:F7) -> 15824357 | G8: =SUM(G5:G7) -> 135976 | H8: =SUM(H5:H7) -> 1837 | I8: =SUM(I5:I7) -> 124 | J8: =SUM(J5:J7) -> 23276290 | K8: =IFERROR(D8/SUM('Raw Data'!$G:$G)*1000,0) -> 2507.1092 | L8: =IFERROR(D8/G8,0) -> 315.04251 | M8: =IFERROR(D8/I8,0) -> 345469.52 | N8: =IFERROR(J8/D8,0) -> 0.54335333

Sheet CAC Lenses
A1: Cost to acquire one client: three ways to read it
A2: All three are correct. They answer different questions. The recommended headline for the board is Lens 1, explained with Lens 2.
A4: Lens | B4: What it answers | C4: Spend included (IDR) | D4: Purchases included | E4: CAC (IDR) | F4: Revenue (IDR) | G4: ROAS | H4: Average order value (IDR) | I4: CAC as % of AOV
A5: Lens 1: Blended CAC | B5: What did every rupiah of website promotion cost per purchase, including brand and traffic investment? | C5: ='Objective Summary'!D8 -> 42838221 | D5: ='Objective Summary'!I8 -> 124 | E5: =IFERROR(C5/D5,0) -> 345469.52 | F5: ='Objective Summary'!J8 -> 23276290 | G5: =IFERROR(F5/C5,0) -> 0.54335333 | H5: =IFERROR(F5/D5,0) -> 187712.02 | I5: =IFERROR(E5/H5,0) -> 1.8404231
A6: Lens 2: Conversion CAC | B6: What did the campaigns built to acquire buyers (Sales objective) cost per purchase? | C6: ='Objective Summary'!D7 -> 13388742 | D6: ='Objective Summary'!I7 -> 121 | E6: =IFERROR(C6/D6,0) -> 110650.76 | F6: ='Objective Summary'!J7 -> 22739149 | G6: =IFERROR(F6/C6,0) -> 1.6983783 | H6: =IFERROR(F6/D6,0) -> 187926.85 | I6: =IFERROR(E6/H6,0) -> 0.58879697
A7: Lens 3: Best engine CAC | B7: What does our best performing acquisition campaign (Cold Start Broad) cost per purchase? | C7: ='Campaign Summary'!F8 -> 10666202 | D7: ='Campaign Summary'!K8 -> 116 | E7: =IFERROR(C7/D7,0) -> 91950.017 | F7: ='Campaign Summary'!L8 -> 21756098 | G7: =IFERROR(F7/C7,0) -> 2.039723 | H7: =IFERROR(F7/D7,0) -> 187552.57 | I7: =IFERROR(E7/H7,0) -> 0.49026264
A9: Brand and traffic investment per purchase | B9: Lens 1 minus Lens 2. This is the part of blended CAC that comes from Awareness and Traffic campaigns. | E9: =E5-E6 -> 234818.76
A11: Reading guide
A12: 1. Lens 1 is the number finance will recognise: total website promotion spend divided by total website purchases.
A13: 2. Lens 2 isolates the campaigns whose job is to convert. Awareness and Traffic campaigns are optimised for reach and landing page views, not purchases, so they rarely receive purchase credit inside a 7-day click or 1-day view window.
A14: 3. Lens 3 shows what the acquisition engine can do at its best and is the benchmark for scaling budget.
A15: 4. A purchase is counted as one acquired client. Meta reports purchase events, not unique customers, so repeat buyers inside the period slightly inflate the client count and slightly understate true CAC.

Sheet Monthly Trend
A1: Monthly trend
A2: July covers 1 to 31 July (Sales campaigns started 17 July). September covers 1 to 8 September only.
A4: Month | B4: Awareness spend (IDR) | C4: Traffic spend (IDR) | D4: Sales spend (IDR) | E4: Total spend (IDR) | F4: Landing page views | G4: Adds to cart | H4: Purchases | I4: Revenue (IDR) | J4: Blended CAC (IDR) | K4: Conversion CAC (IDR) | L4: Blended ROAS | M4: Sales ROAS
A5: 2026-07 | B5: =SUMIFS('Raw Data'!$I:$I,'Raw Data'!$S:$S,$A5,'Raw Data'!$R:$R,"Awareness") -> 7456678 | C5: =SUMIFS('Raw Data'!$I:$I,'Raw Data'!$S:$S,$A5,'Raw Data'!$R:$R,"Traffic") -> 4429554 | D5: =SUMIFS('Raw Data'!$I:$I,'Raw Data'!$S:$S,$A5,'Raw Data'!$R:$R,"Sales") -> 2888133 | E5: =SUM(B5:D5) -> 14774365 | F5: =SUMIFS('Raw Data'!$J:$J,'Raw Data'!$S:$S,$A5) -> 38685 | G5: =SUMIFS('Raw Data'!$M:$M,'Raw Data'!$S:$S,$A5) -> 500 | H5: =SUMIFS('Raw Data'!$K:$K,'Raw Data'!$S:$S,$A5) -> 32 | I5: =SUMIFS('Raw Data'!$L:$L,'Raw Data'!$S:$S,$A5) -> 6135493 | J5: =IFERROR(E5/H5,0) -> 461698.91 | K5: =IFERROR(D5/SUMIFS('Raw Data'!$K:$K,'Raw Data'!$S:$S,$A5,'Raw Data'!$R:$R,"Sales"),0) -> 90254.156 | L5: =IFERROR(I5/E5,0) -> 0.41527964 | M5: =IFERROR(SUMIFS('Raw Data'!$L:$L,'Raw Data'!$S:$S,$A5,'Raw Data'!$R:$R,"Sales")/D5,0) -> 2.1243804
A6: 2026-08 | B6: =SUMIFS('Raw Data'!$I:$I,'Raw Data'!$S:$S,$A6,'Raw Data'!$R:$R,"Awareness") -> 4660328 | C6: =SUMIFS('Raw Data'!$I:$I,'Raw Data'!$S:$S,$A6,'Raw Data'!$R:$R,"Traffic") -> 9284674 | D6: =SUMIFS('Raw Data'!$I:$I,'Raw Data'!$S:$S,$A6,'Raw Data'!$R:$R,"Sales") -> 8875327 | E6: =SUM(B6:D6) -> 22820329 | F6: =SUMIFS('Raw Data'!$J:$J,'Raw Data'!$S:$S,$A6) -> 78132 | G6: =SUMIFS('Raw Data'!$M:$M,'Raw Data'!$S:$S,$A6) -> 1124 | H6: =SUMIFS('Raw Data'!$K:$K,'Raw Data'!$S:$S,$A6) -> 73 | I6: =SUMIFS('Raw Data'!$L:$L,'Raw Data'!$S:$S,$A6) -> 13891743 | J6: =IFERROR(E6/H6,0) -> 312607.25 | K6: =IFERROR(D6/SUMIFS('Raw Data'!$K:$K,'Raw Data'!$S:$S,$A6,'Raw Data'!$R:$R,"Sales"),0) -> 125004.61 | L6: =IFERROR(I6/E6,0) -> 0.6087442 | M6: =IFERROR(SUMIFS('Raw Data'!$L:$L,'Raw Data'!$S:$S,$A6,'Raw Data'!$R:$R,"Sales")/D6,0) -> 1.5240017
A7: 2026-09 | B7: =SUMIFS('Raw Data'!$I:$I,'Raw Data'!$S:$S,$A7,'Raw Data'!$R:$R,"Awareness") -> 1181369 | C7: =SUMIFS('Raw Data'!$I:$I,'Raw Data'!$S:$S,$A7,'Raw Data'!$R:$R,"Traffic") -> 2436876 | D7: =SUMIFS('Raw Data'!$I:$I,'Raw Data'!$S:$S,$A7,'Raw Data'!$R:$R,"Sales") -> 1625282 | E7: =SUM(B7:D7) -> 5243527 | F7: =SUMIFS('Raw Data'!$J:$J,'Raw Data'!$S:$S,$A7) -> 19159 | G7: =SUMIFS('Raw Data'!$M:$M,'Raw Data'!$S:$S,$A7) -> 213 | H7: =SUMIFS('Raw Data'!$K:$K,'Raw Data'!$S:$S,$A7) -> 19 | I7: =SUMIFS('Raw Data'!$L:$L,'Raw Data'!$S:$S,$A7) -> 3249054 | J7: =IFERROR(E7/H7,0) -> 275975.11 | K7: =IFERROR(D7/SUMIFS('Raw Data'!$K:$K,'Raw Data'!$S:$S,$A7,'Raw Data'!$R:$R,"Sales"),0) -> 90293.444 | L7: =IFERROR(I7/E7,0) -> 0.6196314 | M7: =IFERROR(SUMIFS('Raw Data'!$L:$L,'Raw Data'!$S:$S,$A7,'Raw Data'!$R:$R,"Sales")/D7,0) -> 1.8936055
A8: Total | B8: =SUM(B5:B7) -> 13298375 | C8: =SUM(C5:C7) -> 16151104 | D8: =SUM(D5:D7) -> 13388742 | E8: =SUM(E5:E7) -> 42838221 | F8: =SUM(F5:F7) -> 135976 | G8: =SUM(G5:G7) -> 1837 | H8: =SUM(H5:H7) -> 124 | I8: =SUM(I5:I7) -> 23276290 | J8: =IFERROR(E8/H8,0) -> 345469.52 | K8: =IFERROR(D8/SUMIFS('Raw Data'!$K:$K,'Raw Data'!$R:$R,"Sales"),0) -> 110650.76 | L8: =IFERROR(I8/E8,0) -> 0.54335333 | M8: =IFERROR(SUMIFS('Raw Data'!$L:$L,'Raw Data'!$R:$R,"Sales")/D8,0) -> 1.6983783

Sheet Ad Set Performance
A1: Ad set performance
A2: Use this sheet to decide where to scale and where to cut. Sorted by objective, then campaign.
A4: Objective | B4: Campaign name | C4: Ad set name | D4: Days active | E4: Spend (IDR) | F4: Reach | G4: Impressions | H4: Landing page views | I4: Adds to cart | J4: Purchases | K4: Revenue (IDR) | L4: CPM (IDR) | M4: Cost per LPV (IDR) | N4: LPV to ATC rate | O4: ATC to purchase rate | P4: CAC (IDR) | Q4: ROAS
A5: Awareness | B5: Awareness / Reach / CBO / AON | C5: Broad Fashion | D5: 12 | E5: =SUMIFS('Raw Data'!$I:$I,'Raw Data'!$A:$A,$B5,'Raw Data'!$B:$B,$C5) -> 646116 | F5: =SUMIFS('Raw Data'!$F:$F,'Raw Data'!$A:$A,$B5,'Raw Data'!$B:$B,$C5) -> 527633 | G5: =SUMIFS('Raw Data'!$G:$G,'Raw Data'!$A:$A,$B5,'Raw Data'!$B:$B,$C5) -> 535257 | H5: =SUMIFS('Raw Data'!$J:$J,'Raw Data'!$A:$A,$B5,'Raw Data'!$B:$B,$C5) -> 0 | I5: =SUMIFS('Raw Data'!$M:$M,'Raw Data'!$A:$A,$B5,'Raw Data'!$B:$B,$C5) -> 0 | J5: =SUMIFS('Raw Data'!$K:$K,'Raw Data'!$A:$A,$B5,'Raw Data'!$B:$B,$C5) -> 0 | K5: =SUMIFS('Raw Data'!$L:$L,'Raw Data'!$A:$A,$B5,'Raw Data'!$B:$B,$C5) -> 0 | L5: =IFERROR(E5/G5*1000,0) -> 1207.1136 | M5: =IFERROR(E5/H5,0) -> 0 | N5: =IFERROR(I5/H5,0) -> 0 | O5: =IFERROR(J5/I5,0) -> 0 | P5: =IFERROR(E5/J5,0) -> 0 | Q5: =IFERROR(K5/E5,0) -> 0
A6: Awareness | B6: Awareness / Reach / CBO / AON | C6: Fashion Brand | D6: 12 | E6: =SUMIFS('Raw Data'!$I:$I,'Raw Data'!$A:$A,$B6,'Raw Data'!$B:$B,$C6) -> 807913 | F6: =SUMIFS('Raw Data'!$F:$F,'Raw Data'!$A:$A,$B6,'Raw Data'!$B:$B,$C6) -> 666843 | G6: =SUMIFS('Raw Data'!$G:$G,'Raw Data'!$A:$A,$B6,'Raw Data'!$B:$B,$C6) -> 677940 | H6: =SUMIFS('Raw Data'!$J:$J,'Raw Data'!$A:$A,$B6,'Raw Data'!$B:$B,$C6) -> 0 | I6: =SUMIFS('Raw Data'!$M:$M,'Raw Data'!$A:$A,$B6,'Raw Data'!$B:$B,$C6) -> 0 | J6: =SUMIFS('Raw Data'!$K:$K,'Raw Data'!$A:$A,$B6,'Raw Data'!$B:$B,$C6) -> 0 | K6: =SUMIFS('Raw Data'!$L:$L,'Raw Data'!$A:$A,$B6,'Raw Data'!$B:$B,$C6) -> 0 | L6: =IFERROR(E6/G6*1000,0) -> 1191.7176 | M6: =IFERROR(E6/H6,0) -> 0 | N6: =IFERROR(I6/H6,0) -> 0 | O6: =IFERROR(J6/I6,0) -> 0 | P6: =IFERROR(E6/J6,0) -> 0 | Q6: =IFERROR(K6/E6,0) -> 0
A7: Awareness | B7: Awareness / Reach / CBO / AON | C7: Life Style | D7: 12 | E7: =SUMIFS('Raw Data'!$I:$I,'Raw Data'!$A:$A,$B7,'Raw Data'!$B:$B,$C7) -> 1963342 | F7: =SUMIFS('Raw Data'!$F:$F,'Raw Data'!$A:$A,$B7,'Raw Data'!$B:$B,$C7) -> 1637147 | G7: =SUMIFS('Raw Data'!$G:$G,'Raw Data'!$A:$A,$B7,'Raw Data'!$B:$B,$C7) -> 1650256 | H7: =SUMIFS('Raw Data'!$J:$J,'Raw Data'!$A:$A,$B7,'Raw Data'!$B:$B,$C7) -> 0 | I7: =SUMIFS('Raw Data'!$M:$M,'Raw Data'!$A:$A,$B7,'Raw Data'!$B:$B,$C7) -> 0 | J7: =SUMIFS('Raw Data'!$K:$K,'Raw Data'!$A:$A,$B7,'Raw Data'!$B:$B,$C7) -> 0 | K7: =SUMIFS('Raw Data'!$L:$L,'Raw Data'!$A:$A,$B7,'Raw Data'!$B:$B,$C7) -> 0 | L7: =IFERROR(E7/G7*1000,0) -> 1189.7197 | M7: =IFERROR(E7/H7,0) -> 0 | N7: =IFERROR(I7/H7,0) -> 0 | O7: =IFERROR(J7/I7,0) -> 0 | P7: =IFERROR(E7/J7,0) -> 0 | Q7: =IFERROR(K7/E7,0) -> 0
A8: Awareness | B8: Awareness / Reach / CBO / SophieMartin | C8: AW-1 / Broad Cold Audience | D8: 55 | E8: =SUMIFS('Raw Data'!$I:$I,'Raw Data'!$A:$A,$B8,'Raw Data'!$B:$B,$C8) -> 5955833 | F8: =SUMIFS('Raw Data'!$F:$F,'Raw Data'!$A:$A,$B8,'Raw Data'!$B:$B,$C8) -> 4602636 | G8: =SUMIFS('Raw Data'!$G:$G,'Raw Data'!$A:$A,$B8,'Raw Data'!$B:$B,$C8) -> 4646093 | H8: =SUMIFS('Raw Data'!$J:$J,'Raw Data'!$A:$A,$B8,'Raw Data'!$B:$B,$C8) -> 775 | I8: =SUMIFS('Raw Data'!$M:$M,'Raw Data'!$A:$A,$B8,'Raw Data'!$B:$B,$C8) -> 1 | J8: =SUMIFS('Raw Data'!$K:$K,'Raw Data'!$A:$A,$B8,'Raw Data'!$B:$B,$C8) -> 0 | K8: =SUMIFS('Raw Data'!$L:$L,'Raw Data'!$A:$A,$B8,'Raw Data'!$B:$B,$C8) -> 0 | L8: =IFERROR(E8/G8*1000,0) -> 1281.9014 | M8: =IFERROR(E8/H8,0) -> 7684.9458 | N8: =IFERROR(I8/H8,0) -> 0.0012903226 | O8: =IFERROR(J8/I8,0) -> 0 | P8: =IFERROR(E8/J8,0) -> 0 | Q8: =IFERROR(K8/E8,0) -> 0
A9: Awareness | B9: Awareness / Reach / CBO / SophieMartin | C9: AW-2 / Interest - Fashion & Style | D9: 55 | E9: =SUMIFS('Raw Data'!$I:$I,'Raw Data'!$A:$A,$B9,'Raw Data'!$B:$B,$C9) -> 1936383 | F9: =SUMIFS('Raw Data'!$F:$F,'Raw Data'!$A:$A,$B9,'Raw Data'!$B:$B,$C9) -> 1565042 | G9: =SUMIFS('Raw Data'!$G:$G,'Raw Data'!$A:$A,$B9,'Raw Data'!$B:$B,$C9) -> 1576148 | H9: =SUMIFS('Raw Data'!$J:$J,'Raw Data'!$A:$A,$B9,'Raw Data'!$B:$B,$C9) -> 280 | I9: =SUMIFS('Raw Data'!$M:$M,'Raw Data'!$A:$A,$B9,'Raw Data'!$B:$B,$C9) -> 2 | J9: =SUMIFS('Raw Data'!$K:$K,'Raw Data'!$A:$A,$B9,'Raw Data'!$B:$B,$C9) -> 0 | K9: =SUMIFS('Raw Data'!$L:$L,'Raw Data'!$A:$A,$B9,'Raw Data'!$B:$B,$C9) -> 0 | L9: =IFERROR(E9/G9*1000,0) -> 1228.554 | M9: =IFERROR(E9/H9,0) -> 6915.6536 | N9: =IFERROR(I9/H9,0) -> 0.0071428571 | O9: =IFERROR(J9/I9,0) -> 0 | P9: =IFERROR(E9/J9,0) -> 0 | Q9: =IFERROR(K9/E9,0) -> 0
A10: Awareness | B10: Awareness / Reach / CBO / SophieMartin | C10: AW-3 / Lookalike 3-5% (Engagers) | D10: 55 | E10: =SUMIFS('Raw Data'!$I:$I,'Raw Data'!$A:$A,$B10,'Raw Data'!$B:$B,$C10) -> 1988788 | F10: =SUMIFS('Raw Data'!$F:$F,'Raw Data'!$A:$A,$B10,'Raw Data'!$B:$B,$C10) -> 1469618 | G10: =SUMIFS('Raw Data'!$G:$G,'Raw Data'!$A:$A,$B10,'Raw Data'!$B:$B,$C10) -> 1475580 | H10: =SUMIFS('Raw Data'!$J:$J,'Raw Data'!$A:$A,$B10,'Raw Data'!$B:$B,$C10) -> 341 | I10: =SUMIFS('Raw Data'!$M:$M,'Raw Data'!$A:$A,$B10,'Raw Data'!$B:$B,$C10) -> 3 | J10: =SUMIFS('Raw Data'!$K:$K,'Raw Data'!$A:$A,$B10,'Raw Data'!$B:$B,$C10) -> 0 | K10: =SUMIFS('Raw Data'!$L:$L,'Raw Data'!$A:$A,$B10,'Raw Data'!$B:$B,$C10) -> 0 | L10: =IFERROR(E10/G10*1000,0) -> 1347.8009 | M10: =IFERROR(E10/H10,0) -> 5832.2229 | N10: =IFERROR(I10/H10,0) -> 0.008797654 | O10: =IFERROR(J10/I10,0) -> 0 | P10: =IFERROR(E10/J10,0) -> 0 | Q10: =IFERROR(K10/E10,0) -> 0
A11: Traffic | B11: Traffic / LPV / Web / SophieMartin | C11: CL-1 Online Shopper Behaviour | D11: 54 | E11: =SUMIFS('Raw Data'!$I:$I,'Raw Data'!$A:$A,$B11,'Raw Data'!$B:$B,$C11) -> 12294530 | F11: =SUMIFS('Raw Data'!$F:$F,'Raw Data'!$A:$A,$B11,'Raw Data'!$B:$B,$C11) -> 3745609 | G11: =SUMIFS('Raw Data'!$G:$G,'Raw Data'!$A:$A,$B11,'Raw Data'!$B:$B,$C11) -> 4574438 | H11: =SUMIFS('Raw Data'!$J:$J,'Raw Data'!$A:$A,$B11,'Raw Data'!$B:$B,$C11) -> 88075 | I11: =SUMIFS('Raw Data'!$M:$M,'Raw Data'!$A:$A,$B11,'Raw Data'!$B:$B,$C11) -> 253 | J11: =SUMIFS('Raw Data'!$K:$K,'Raw Data'!$A:$A,$B11,'Raw Data'!$B:$B,$C11) -> 2 | K11: =SUMIFS('Raw Data'!$L:$L,'Raw Data'!$A:$A,$B11,'Raw Data'!$B:$B,$C11) -> 377982 | L11: =IFERROR(E11/G11*1000,0) -> 2687.6591 | M11: =IFERROR(E11/H11,0) -> 139.5916 | N11: =IFERROR(I11/H11,0) -> 0.0028725518 | O11: =IFERROR(J11/I11,0) -> 0.0079051383 | P11: =IFERROR(E11/J11,0) -> 6147265 | Q11: =IFERROR(K11/E11,0) -> 0.030743916
A12: Traffic | B12: Traffic / LPV / Web / SophieMartin | C12: CL-2 Video Viewers Retarget | D12: 54 | E12: =SUMIFS('Raw Data'!$I:$I,'Raw Data'!$A:$A,$B12,'Raw Data'!$B:$B,$C12) -> 549805 | F12: =SUMIFS('Raw Data'!$F:$F,'Raw Data'!$A:$A,$B12,'Raw Data'!$B:$B,$C12) -> 112323 | G12: =SUMIFS('Raw Data'!$G:$G,'Raw Data'!$A:$A,$B12,'Raw Data'!$B:$B,$C12) -> 133045 | H12: =SUMIFS('Raw Data'!$J:$J,'Raw Data'!$A:$A,$B12,'Raw Data'!$B:$B,$C12) -> 3813 | I12: =SUMIFS('Raw Data'!$M:$M,'Raw Data'!$A:$A,$B12,'Raw Data'!$B:$B,$C12) -> 20 | J12: =SUMIFS('Raw Data'!$K:$K,'Raw Data'!$A:$A,$B12,'Raw Data'!$B:$B,$C12) -> 0 | K12: =SUMIFS('Raw Data'!$L:$L,'Raw Data'!$A:$A,$B12,'Raw Data'!$B:$B,$C12) -> 0 | L12: =IFERROR(E12/G12*1000,0) -> 4132.474 | M12: =IFERROR(E12/H12,0) -> 144.19224 | N12: =IFERROR(I12/H12,0) -> 0.0052452137 | O12: =IFERROR(J12/I12,0) -> 0 | P12: =IFERROR(E12/J12,0) -> 0 | Q12: =IFERROR(K12/E12,0) -> 0
A13: Traffic | B13: Traffic / LPV / Web / SophieMartin | C13: CL-3 Lookalike 1-3% (Web Visitors) | D13: 53 | E13: =SUMIFS('Raw Data'!$I:$I,'Raw Data'!$A:$A,$B13,'Raw Data'!$B:$B,$C13) -> 3306769 | F13: =SUMIFS('Raw Data'!$F:$F,'Raw Data'!$A:$A,$B13,'Raw Data'!$B:$B,$C13) -> 899301 | G13: =SUMIFS('Raw Data'!$G:$G,'Raw Data'!$A:$A,$B13,'Raw Data'!$B:$B,$C13) -> 1066585 | H13: =SUMIFS('Raw Data'!$J:$J,'Raw Data'!$A:$A,$B13,'Raw Data'!$B:$B,$C13) -> 27019 | I13: =SUMIFS('Raw Data'!$M:$M,'Raw Data'!$A:$A,$B13,'Raw Data'!$B:$B,$C13) -> 59 | J13: =SUMIFS('Raw Data'!$K:$K,'Raw Data'!$A:$A,$B13,'Raw Data'!$B:$B,$C13) -> 1 | K13: =SUMIFS('Raw Data'!$L:$L,'Raw Data'!$A:$A,$B13,'Raw Data'!$B:$B,$C13) -> 159159 | L13: =IFERROR(E13/G13*1000,0) -> 3100.3333 | M13: =IFERROR(E13/H13,0) -> 122.3868 | N13: =IFERROR(I13/H13,0) -> 0.0021836485 | O13: =IFERROR(J13/I13,0) -> 0.016949153 | P13: =IFERROR(E13/J13,0) -> 3306769 | Q13: =IFERROR(K13/E13,0) -> 0.048131273
A14: Sales | B14: Sales / Purchase / CBO / ColdStart Broad / SophieMartin / Jul26 | C14: ADS / Broad Advantage+ / Wanita 18-45 / ID / Feed-Story-Reels | D14: 54 | E14: =SUMIFS('Raw Data'!$I:$I,'Raw Data'!$A:$A,$B14,'Raw Data'!$B:$B,$C14) -> 10666202 | F14: =SUMIFS('Raw Data'!$F:$F,'Raw Data'!$A:$A,$B14,'Raw Data'!$B:$B,$C14) -> 499852 | G14: =SUMIFS('Raw Data'!$G:$G,'Raw Data'!$A:$A,$B14,'Raw Data'!$B:$B,$C14) -> 583832 | H14: =SUMIFS('Raw Data'!$J:$J,'Raw Data'!$A:$A,$B14,'Raw Data'!$B:$B,$C14) -> 13399 | I14: =SUMIFS('Raw Data'!$M:$M,'Raw Data'!$A:$A,$B14,'Raw Data'!$B:$B,$C14) -> 1374 | J14: =SUMIFS('Raw Data'!$K:$K,'Raw Data'!$A:$A,$B14,'Raw Data'!$B:$B,$C14) -> 116 | K14: =SUMIFS('Raw Data'!$L:$L,'Raw Data'!$A:$A,$B14,'Raw Data'!$B:$B,$C14) -> 21756098 | L14: =IFERROR(E14/G14*1000,0) -> 18269.3 | M14: =IFERROR(E14/H14,0) -> 796.04463 | N14: =IFERROR(I14/H14,0) -> 0.10254497 | O14: =IFERROR(J14/I14,0) -> 0.084425036 | P14: =IFERROR(E14/J14,0) -> 91950.017 | Q14: =IFERROR(K14/E14,0) -> 2.039723
A15: Sales | B15: Sales / Retargeting / CBO / SophieMartin | C15: RT-1 / Hot / Cart+Checkout 14D / Purchase | D15: 19 | E15: =SUMIFS('Raw Data'!$I:$I,'Raw Data'!$A:$A,$B15,'Raw Data'!$B:$B,$C15) -> 394367 | F15: =SUMIFS('Raw Data'!$F:$F,'Raw Data'!$A:$A,$B15,'Raw Data'!$B:$B,$C15) -> 6337 | G15: =SUMIFS('Raw Data'!$G:$G,'Raw Data'!$A:$A,$B15,'Raw Data'!$B:$B,$C15) -> 11846 | H15: =SUMIFS('Raw Data'!$J:$J,'Raw Data'!$A:$A,$B15,'Raw Data'!$B:$B,$C15) -> 147 | I15: =SUMIFS('Raw Data'!$M:$M,'Raw Data'!$A:$A,$B15,'Raw Data'!$B:$B,$C15) -> 23 | J15: =SUMIFS('Raw Data'!$K:$K,'Raw Data'!$A:$A,$B15,'Raw Data'!$B:$B,$C15) -> 2 | K15: =SUMIFS('Raw Data'!$L:$L,'Raw Data'!$A:$A,$B15,'Raw Data'!$B:$B,$C15) -> 387657 | L15: =IFERROR(E15/G15*1000,0) -> 33291.153 | M15: =IFERROR(E15/H15,0) -> 2682.7687 | N15: =IFERROR(I15/H15,0) -> 0.15646259 | O15: =IFERROR(J15/I15,0) -> 0.086956522 | P15: =IFERROR(E15/J15,0) -> 197183.5 | Q15: =IFERROR(K15/E15,0) -> 0.98298539
A16: Sales | B16: Sales / Retargeting / CBO / SophieMartin | C16: RT-2 / Warm / Product Viewers 30-180D / Purchase | D16: 19 | E16: =SUMIFS('Raw Data'!$I:$I,'Raw Data'!$A:$A,$B16,'Raw Data'!$B:$B,$C16) -> 1984194 | F16: =SUMIFS('Raw Data'!$F:$F,'Raw Data'!$A:$A,$B16,'Raw Data'!$B:$B,$C16) -> 61738 | G16: =SUMIFS('Raw Data'!$G:$G,'Raw Data'!$A:$A,$B16,'Raw Data'!$B:$B,$C16) -> 117570 | H16: =SUMIFS('Raw Data'!$J:$J,'Raw Data'!$A:$A,$B16,'Raw Data'!$B:$B,$C16) -> 1768 | I16: =SUMIFS('Raw Data'!$M:$M,'Raw Data'!$A:$A,$B16,'Raw Data'!$B:$B,$C16) -> 78 | J16: =SUMIFS('Raw Data'!$K:$K,'Raw Data'!$A:$A,$B16,'Raw Data'!$B:$B,$C16) -> 1 | K16: =SUMIFS('Raw Data'!$L:$L,'Raw Data'!$A:$A,$B16,'Raw Data'!$B:$B,$C16) -> 193171 | L16: =IFERROR(E16/G16*1000,0) -> 16876.703 | M16: =IFERROR(E16/H16,0) -> 1122.2817 | N16: =IFERROR(I16/H16,0) -> 0.044117647 | O16: =IFERROR(J16/I16,0) -> 0.012820513 | P16: =IFERROR(E16/J16,0) -> 1984194 | Q16: =IFERROR(K16/E16,0) -> 0.097354896
A17: Sales | B17: Sales / Retargeting / CBO / SophieMartin | C17: RT-3 / Warm / Social Engagers (Video+IG) / Purchase | D17: 4 | E17: =SUMIFS('Raw Data'!$I:$I,'Raw Data'!$A:$A,$B17,'Raw Data'!$B:$B,$C17) -> 343979 | F17: =SUMIFS('Raw Data'!$F:$F,'Raw Data'!$A:$A,$B17,'Raw Data'!$B:$B,$C17) -> 30278 | G17: =SUMIFS('Raw Data'!$G:$G,'Raw Data'!$A:$A,$B17,'Raw Data'!$B:$B,$C17) -> 38109 | H17: =SUMIFS('Raw Data'!$J:$J,'Raw Data'!$A:$A,$B17,'Raw Data'!$B:$B,$C17) -> 359 | I17: =SUMIFS('Raw Data'!$M:$M,'Raw Data'!$A:$A,$B17,'Raw Data'!$B:$B,$C17) -> 24 | J17: =SUMIFS('Raw Data'!$K:$K,'Raw Data'!$A:$A,$B17,'Raw Data'!$B:$B,$C17) -> 2 | K17: =SUMIFS('Raw Data'!$L:$L,'Raw Data'!$A:$A,$B17,'Raw Data'!$B:$B,$C17) -> 402223 | L17: =IFERROR(E17/G17*1000,0) -> 9026.188 | M17: =IFERROR(E17/H17,0) -> 958.15877 | N17: =IFERROR(I17/H17,0) -> 0.066852368 | O17: =IFERROR(J17/I17,0) -> 0.083333333 | P17: =IFERROR(E17/J17,0) -> 171989.5 | Q17: =IFERROR(K17/E17,0) -> 1.1693243
A18: Total | E18: =SUM(E5:E17) -> 42838221 | F18: =SUM(F5:F17) -> 15824357 | G18: =SUM(G5:G17) -> 17086699 | H18: =SUM(H5:H17) -> 135976 | I18: =SUM(I5:I17) -> 1837 | J18: =SUM(J5:J17) -> 124 | K18: =SUM(K5:K17) -> 23276290 | L18: =IFERROR(E18/G18*1000,0) -> 2507.1092 | M18: =IFERROR(E18/H18,0) -> 315.04251 | N18: =IFERROR(I18/H18,0) -> 0.013509737 | O18: =IFERROR(J18/I18,0) -> 0.067501361 | P18: =IFERROR(E18/J18,0) -> 345469.52 | Q18: =IFERROR(K18/E18,0) -> 0.54335333

Sheet Funnel
A1: Website funnel, all campaigns combined
A2: Each stage is a Meta reported event. Step rate is the share of the previous stage that reached this stage.
A4: Stage | B4: Count | C4: Step rate from previous stage | D4: Rate from reach | E4: Cost per event (IDR)
A5: People reached | B5: ='Objective Summary'!F8 -> 15824357 | D5: =IFERROR(B5/$B$5,0) -> 1 | E5: =IFERROR('Objective Summary'!$D$8/B5,0) -> 2.7071066
A6: Landing page views | B6: ='Objective Summary'!G8 -> 135976 | C6: =IFERROR(B6/B5,0) -> 0.0085928294 | D6: =IFERROR(B6/$B$5,0) -> 0.0085928294 | E6: =IFERROR('Objective Summary'!$D$8/B6,0) -> 315.04251
A7: Adds to cart | B7: ='Objective Summary'!H8 -> 1837 | C7: =IFERROR(B7/B6,0) -> 0.013509737 | D7: =IFERROR(B7/$B$5,0) -> 0.00011608687 | E7: =IFERROR('Objective Summary'!$D$8/B7,0) -> 23319.663
A8: Purchases | B8: ='Objective Summary'!I8 -> 124 | C8: =IFERROR(B8/B7,0) -> 0.067501361 | D8: =IFERROR(B8/$B$5,0) -> 7.8360214e-06 | E8: =IFERROR('Objective Summary'!$D$8/B8,0) -> 345469.52
A10: Cart value left behind
A11: Add to cart value (IDR) | B11: =SUM('Raw Data'!$N:$N) -> 307837889
A12: Purchase value (IDR) | B12: ='Objective Summary'!J8 -> 23276290
A13: Cart value not converted (IDR) | B13: =B11-B12 -> 284561599
A14: Share of cart value converted | B14: =IFERROR(B12/B11,0) -> 0.075612167
A16: Note: add to cart value counts every cart event, so the same shopper adding twice is counted twice. Treat the gap as a direction, not an exact leak.
