Workbook

Sheet Dashboard
A1: TONI BLACK — AFFILIATE DASHBOARD
A2: Seluruh angka di sheet ini rumus. Tidak ada yang perlu diketik.
A4: RINGKASAN
A5: Jumlah Affiliate | B5: =COUNTA('Daftar Affiliate'!$B$6:$B$105) -> 5
A6: Affiliate Aktif | B6: =COUNTIF('Daftar Affiliate'!$R$6:$R$105,"Aktif") -> 3
A7: Total Followers | B7: =SUM('Daftar Affiliate'!$F$6:$F$105) -> 799700
A8: Total GMV per Bulan | B8: =SUM('Daftar Affiliate'!$J$6:$J$105) -> 68750000
A9: Total Biaya Komisi | B9: =SUM('Daftar Affiliate'!$M$6:$M$105) -> 7299000
A10: GMV Bersih per Bulan | B10: =SUM('Daftar Affiliate'!$N$6:$N$105) -> 61451000
A11: Rata-rata GMV per Affiliate | B11: =IFERROR(SUM('Daftar Affiliate'!$J$6:$J$105)/COUNTA('Daftar Affiliate'!$B$6:$B$105),0) -> 13750000
A12: GMV per 1.000 Followers (keseluruhan) | B12: =IFERROR(SUM('Daftar Affiliate'!$J$6:$J$105)/SUM('Daftar Affiliate'!$F$6:$F$105)*1000,0) -> 85969.739
A13: Komisi Efektif | B13: =IFERROR(SUM('Daftar Affiliate'!$M$6:$M$105)/SUM('Daftar Affiliate'!$J$6:$J$105),0) -> 0.10616727
A16: PER TIER
A17: Tier | B17: Jumlah | C17: Total Followers | D17: Total GMV | E17: GMV per 1.000 Followers | F17: Kontribusi GMV
A18: Nano | B18: =COUNTIF('Daftar Affiliate'!$G$6:$G$105,$A18) -> 2 | C18: =SUMIF('Daftar Affiliate'!$G$6:$G$105,$A18,'Daftar Affiliate'!$F$6:$F$105) -> 11700 | D18: =SUMIF('Daftar Affiliate'!$G$6:$G$105,$A18,'Daftar Affiliate'!$J$6:$J$105) -> 8950000 | E18: =IFERROR($D18/$C18*1000,0) -> 764957.26 | F18: =IFERROR($D18/SUM('Daftar Affiliate'!$J$6:$J$105),0) -> 0.13018182
A19: Micro | B19: =COUNTIF('Daftar Affiliate'!$G$6:$G$105,$A19) -> 1 | C19: =SUMIF('Daftar Affiliate'!$G$6:$G$105,$A19,'Daftar Affiliate'!$F$6:$F$105) -> 46000 | D19: =SUMIF('Daftar Affiliate'!$G$6:$G$105,$A19,'Daftar Affiliate'!$J$6:$J$105) -> 21400000 | E19: =IFERROR($D19/$C19*1000,0) -> 465217.39 | F19: =IFERROR($D19/SUM('Daftar Affiliate'!$J$6:$J$105),0) -> 0.31127273
A20: Mid | B20: =COUNTIF('Daftar Affiliate'!$G$6:$G$105,$A20) -> 1 | C20: =SUMIF('Daftar Affiliate'!$G$6:$G$105,$A20,'Daftar Affiliate'!$F$6:$F$105) -> 132000 | D20: =SUMIF('Daftar Affiliate'!$G$6:$G$105,$A20,'Daftar Affiliate'!$J$6:$J$105) -> 4900000 | E20: =IFERROR($D20/$C20*1000,0) -> 37121.212 | F20: =IFERROR($D20/SUM('Daftar Affiliate'!$J$6:$J$105),0) -> 0.071272727
A21: Macro | B21: =COUNTIF('Daftar Affiliate'!$G$6:$G$105,$A21) -> 1 | C21: =SUMIF('Daftar Affiliate'!$G$6:$G$105,$A21,'Daftar Affiliate'!$F$6:$F$105) -> 610000 | D21: =SUMIF('Daftar Affiliate'!$G$6:$G$105,$A21,'Daftar Affiliate'!$J$6:$J$105) -> 33500000 | E21: =IFERROR($D21/$C21*1000,0) -> 54918.033 | F21: =IFERROR($D21/SUM('Daftar Affiliate'!$J$6:$J$105),0) -> 0.48727273
A22: Mega | B22: =COUNTIF('Daftar Affiliate'!$G$6:$G$105,$A22) -> 0 | C22: =SUMIF('Daftar Affiliate'!$G$6:$G$105,$A22,'Daftar Affiliate'!$F$6:$F$105) -> 0 | D22: =SUMIF('Daftar Affiliate'!$G$6:$G$105,$A22,'Daftar Affiliate'!$J$6:$J$105) -> 0 | E22: =IFERROR($D22/$C22*1000,0) -> 0 | F22: =IFERROR($D22/SUM('Daftar Affiliate'!$J$6:$J$105),0) -> 0
A25: PER PLATFORM
A26: Platform | B26: Jumlah | C26: Total GMV | D26: Kontribusi GMV
A27: TikTok | B27: =COUNTIF('Daftar Affiliate'!$D$6:$D$105,$A27) -> 2 | C27: =SUMIF('Daftar Affiliate'!$D$6:$D$105,$A27,'Daftar Affiliate'!$J$6:$J$105) -> 40300000 | D27: =IFERROR($C27/SUM('Daftar Affiliate'!$J$6:$J$105),0) -> 0.58618182
A28: TikTok Shop | B28: =COUNTIF('Daftar Affiliate'!$D$6:$D$105,$A28) -> 1 | C28: =SUMIF('Daftar Affiliate'!$D$6:$D$105,$A28,'Daftar Affiliate'!$J$6:$J$105) -> 21400000 | D28: =IFERROR($C28/SUM('Daftar Affiliate'!$J$6:$J$105),0) -> 0.31127273
A29: Instagram | B29: =COUNTIF('Daftar Affiliate'!$D$6:$D$105,$A29) -> 1 | C29: =SUMIF('Daftar Affiliate'!$D$6:$D$105,$A29,'Daftar Affiliate'!$J$6:$J$105) -> 4900000 | D29: =IFERROR($C29/SUM('Daftar Affiliate'!$J$6:$J$105),0) -> 0.071272727
A30: Shopee Live | B30: =COUNTIF('Daftar Affiliate'!$D$6:$D$105,$A30) -> 1 | C30: =SUMIF('Daftar Affiliate'!$D$6:$D$105,$A30,'Daftar Affiliate'!$J$6:$J$105) -> 2150000 | D30: =IFERROR($C30/SUM('Daftar Affiliate'!$J$6:$J$105),0) -> 0.031272727
A31: YouTube | B31: =COUNTIF('Daftar Affiliate'!$D$6:$D$105,$A31) -> 0 | C31: =SUMIF('Daftar Affiliate'!$D$6:$D$105,$A31,'Daftar Affiliate'!$J$6:$J$105) -> 0 | D31: =IFERROR($C31/SUM('Daftar Affiliate'!$J$6:$J$105),0) -> 0
A33: 5 TERATAS — GMV PER BULAN
A34: Siapa yang menghasilkan paling banyak.
A35: # | B35: Nama Affiliate | C35: Tier | D35: GMV per Bulan | E35: GMV per 1.000 Followers
A36: 1 | B36: =IFERROR(INDEX('Daftar Affiliate'!$B$6:$B$105,MATCH(1,'Daftar Affiliate'!$V$6:$V$105,0)),"") -> Aditya Wijaya | C36: =IFERROR(INDEX('Daftar Affiliate'!$G$6:$G$105,MATCH(1,'Daftar Affiliate'!$V$6:$V$105,0)),"") -> Macro | D36: =IFERROR(INDEX('Daftar Affiliate'!$J$6:$J$105,MATCH(1,'Daftar Affiliate'!$V$6:$V$105,0)),"") -> 33500000 | E36: =IFERROR(INDEX('Daftar Affiliate'!$O$6:$O$105,MATCH(1,'Daftar Affiliate'!$V$6:$V$105,0)),"") -> 54918.033
A37: 2 | B37: =IFERROR(INDEX('Daftar Affiliate'!$B$6:$B$105,MATCH(2,'Daftar Affiliate'!$V$6:$V$105,0)),"") -> Bagas Adi | C37: =IFERROR(INDEX('Daftar Affiliate'!$G$6:$G$105,MATCH(2,'Daftar Affiliate'!$V$6:$V$105,0)),"") -> Micro | D37: =IFERROR(INDEX('Daftar Affiliate'!$J$6:$J$105,MATCH(2,'Daftar Affiliate'!$V$6:$V$105,0)),"") -> 21400000 | E37: =IFERROR(INDEX('Daftar Affiliate'!$O$6:$O$105,MATCH(2,'Daftar Affiliate'!$V$6:$V$105,0)),"") -> 465217.39
A38: 3 | B38: =IFERROR(INDEX('Daftar Affiliate'!$B$6:$B$105,MATCH(3,'Daftar Affiliate'!$V$6:$V$105,0)),"") -> Rizky Pratama | C38: =IFERROR(INDEX('Daftar Affiliate'!$G$6:$G$105,MATCH(3,'Daftar Affiliate'!$V$6:$V$105,0)),"") -> Nano | D38: =IFERROR(INDEX('Daftar Affiliate'!$J$6:$J$105,MATCH(3,'Daftar Affiliate'!$V$6:$V$105,0)),"") -> 6800000 | E38: =IFERROR(INDEX('Daftar Affiliate'!$O$6:$O$105,MATCH(3,'Daftar Affiliate'!$V$6:$V$105,0)),"") -> 800000
A39: 4 | B39: =IFERROR(INDEX('Daftar Affiliate'!$B$6:$B$105,MATCH(4,'Daftar Affiliate'!$V$6:$V$105,0)),"") -> Dimas Nugroho | C39: =IFERROR(INDEX('Daftar Affiliate'!$G$6:$G$105,MATCH(4,'Daftar Affiliate'!$V$6:$V$105,0)),"") -> Mid | D39: =IFERROR(INDEX('Daftar Affiliate'!$J$6:$J$105,MATCH(4,'Daftar Affiliate'!$V$6:$V$105,0)),"") -> 4900000 | E39: =IFERROR(INDEX('Daftar Affiliate'!$O$6:$O$105,MATCH(4,'Daftar Affiliate'!$V$6:$V$105,0)),"") -> 37121.212
A40: 5 | B40: =IFERROR(INDEX('Daftar Affiliate'!$B$6:$B$105,MATCH(5,'Daftar Affiliate'!$V$6:$V$105,0)),"") -> Fajar Ramadhan | C40: =IFERROR(INDEX('Daftar Affiliate'!$G$6:$G$105,MATCH(5,'Daftar Affiliate'!$V$6:$V$105,0)),"") -> Nano | D40: =IFERROR(INDEX('Daftar Affiliate'!$J$6:$J$105,MATCH(5,'Daftar Affiliate'!$V$6:$V$105,0)),"") -> 2150000 | E40: =IFERROR(INDEX('Daftar Affiliate'!$O$6:$O$105,MATCH(5,'Daftar Affiliate'!$V$6:$V$105,0)),"") -> 671875
A42: 5 TERATAS — GMV PER 1.000 FOLLOWERS
A43: Siapa yang menjual paling efektif untuk ukurannya. Ini yang biasanya berbeda dari daftar di atas.
A44: # | B44: Nama Affiliate | C44: Tier | D44: GMV per Bulan | E44: GMV per 1.000 Followers
A45: 1 | B45: =IFERROR(INDEX('Daftar Affiliate'!$B$6:$B$105,MATCH(1,'Daftar Affiliate'!$W$6:$W$105,0)),"") -> Rizky Pratama | C45: =IFERROR(INDEX('Daftar Affiliate'!$G$6:$G$105,MATCH(1,'Daftar Affiliate'!$W$6:$W$105,0)),"") -> Nano | D45: =IFERROR(INDEX('Daftar Affiliate'!$J$6:$J$105,MATCH(1,'Daftar Affiliate'!$W$6:$W$105,0)),"") -> 6800000 | E45: =IFERROR(INDEX('Daftar Affiliate'!$O$6:$O$105,MATCH(1,'Daftar Affiliate'!$W$6:$W$105,0)),"") -> 800000
A46: 2 | B46: =IFERROR(INDEX('Daftar Affiliate'!$B$6:$B$105,MATCH(2,'Daftar Affiliate'!$W$6:$W$105,0)),"") -> Fajar Ramadhan | C46: =IFERROR(INDEX('Daftar Affiliate'!$G$6:$G$105,MATCH(2,'Daftar Affiliate'!$W$6:$W$105,0)),"") -> Nano | D46: =IFERROR(INDEX('Daftar Affiliate'!$J$6:$J$105,MATCH(2,'Daftar Affiliate'!$W$6:$W$105,0)),"") -> 2150000 | E46: =IFERROR(INDEX('Daftar Affiliate'!$O$6:$O$105,MATCH(2,'Daftar Affiliate'!$W$6:$W$105,0)),"") -> 671875
A47: 3 | B47: =IFERROR(INDEX('Daftar Affiliate'!$B$6:$B$105,MATCH(3,'Daftar Affiliate'!$W$6:$W$105,0)),"") -> Bagas Adi | C47: =IFERROR(INDEX('Daftar Affiliate'!$G$6:$G$105,MATCH(3,'Daftar Affiliate'!$W$6:$W$105,0)),"") -> Micro | D47: =IFERROR(INDEX('Daftar Affiliate'!$J$6:$J$105,MATCH(3,'Daftar Affiliate'!$W$6:$W$105,0)),"") -> 21400000 | E47: =IFERROR(INDEX('Daftar Affiliate'!$O$6:$O$105,MATCH(3,'Daftar Affiliate'!$W$6:$W$105,0)),"") -> 465217.39
...

Sheet Referensi
A1: REFERENSI
A2: Ubah angka di sini kalau definisinya berubah. Semua sheet lain mengikuti.
A4: TIER BERDASARKAN FOLLOWERS | D4: PLATFORM | F4: STATUS
A5: Batas Bawah Followers | B5: Tier | D5: TikTok | F5: Aktif
A6: 0 | B6: Nano | D6: TikTok Shop | F6: Baru
A7: 10000 | B7: Micro | D7: Instagram | F7: Pantau
A8: 100000 | B8: Mid | D8: Shopee Live | F8: Berhenti
A9: 500000 | B9: Macro | D9: YouTube
A10: 1000000 | B10: Mega
A12: Ambang ini standar industri KOL, bukan angka Toni Black. Ganti kalau perlu.
A15: ARTI WARNA
A16: Teks biru, latar krem | B16: Kolom isian. Hanya ini yang Anda ketik.
A17: Teks hitam, latar abu | B17: Kolom rumus. Jangan diketik, nanti rumusnya hilang.
A18: Latar abu tua | B18: Kolom bantu untuk Dashboard. Boleh disembunyikan.
A21: CARA PAKAI
A22: 1. Isi Daftar Affiliate. Kolom wajib: Nama, Platform, Followers, Sales per Bulan.
A23: 2. Tier, komisi, GMV bersih, dan semua metrik efisiensi terisi sendiri.
A24: 3. Catat GMV tiap bulan di sheet Rekap Bulanan untuk melihat trennya.
A25: 4. Dashboard terisi otomatis. Tidak ada yang perlu diketik di sana.
A26: 5. Hapus baris contoh (baris 6 sampai 10 di Daftar Affiliate) sebelum dipakai.
A29: KENAPA ADA KOLOM GMV PER 1.000 FOLLOWERS
A30: Followers besar tidak berarti penjualan besar. Kolom itu menunjukkan berapa rupiah yang dihasilkan tiap 1.000 followers,
A31: jadi affiliate kecil yang menjual efektif bisa terlihat, dan itu tidak akan kelihatan kalau daftarnya cuma diurutkan dari followers.

Sheet Daftar Affiliate
A1: DAFTAR AFFILIATE
A2: Isi kolom krem saja. Kolom abu terisi sendiri.
A4: No | B4: Nama Affiliate | C4: Username / Handle | D4: Platform | E4: Link Profil | F4: Followers | G4: Tier | H4: Rata-rata Views/Konten | I4: Konten/Bulan | J4: Sales per Bulan (GMV) | K4: Order/Bulan | L4: Komisi % | M4: Biaya Komisi | N4: GMV Bersih | O4: GMV per 1.000 Followers | P4: Nilai Order Rata-rata | Q4: GMV per 1.000 Views | R4: Status | S4: Tanggal Gabung | T4: PIC | U4: Catatan | V4: Peringkat GMV | W4: Peringkat Efisiensi
A6: =IF($B6="","",ROW()-5) -> 1 | B6: Rizky Pratama | C6: @rizkyfits | D6: TikTok | E6: tiktok.com/@rizkyfits | F6: 8500 | G6: =IF($F6="","",LOOKUP($F6,Referensi!$A$6:$A$10,Referensi!$B$6:$B$10)) -> Nano | H6: 42000 | I6: 12 | J6: 6800000 | K6: 34 | L6: 0.12 | M6: =IF(OR($J6="",$L6=""),"",$J6*$L6) -> 816000 | N6: =IF($J6="","",$J6-$M6) -> 5984000 | O6: =IFERROR(IF(OR($J6="",$F6=""),"",$J6/$F6*1000),"") -> 800000 | P6: =IFERROR(IF(OR($J6="",$K6=""),"",$J6/$K6),"") -> 200000 | Q6: =IFERROR(IF(OR($J6="",$H6="",$I6=""),"",$J6/($H6*$I6)*1000),"") -> 13492.063 | R6: Aktif | S6: 2026-03-14 | T6: Nuri | U6: Konversi tinggi walau followers kecil | V6: =IF($J6="","",RANK($J6,$J$6:$J$105,0)+COUNTIF($J$6:$J6,$J6)-1) -> 3 | W6: =IF($O6="","",RANK($O6,$O$6:$O$105,0)+COUNTIF($O$6:$O6,$O6)-1) -> 1
A7: =IF($B7="","",ROW()-5) -> 2 | B7: Bagas Adi | C7: @bagasdaily | D7: TikTok Shop | E7: tiktok.com/@bagasdaily | F7: 46000 | G7: =IF($F7="","",LOOKUP($F7,Referensi!$A$6:$A$10,Referensi!$B$6:$B$10)) -> Micro | H7: 118000 | I7: 20 | J7: 21400000 | K7: 102 | L7: 0.1 | M7: =IF(OR($J7="",$L7=""),"",$J7*$L7) -> 2140000 | N7: =IF($J7="","",$J7-$M7) -> 19260000 | O7: =IFERROR(IF(OR($J7="",$F7=""),"",$J7/$F7*1000),"") -> 465217.39 | P7: =IFERROR(IF(OR($J7="",$K7=""),"",$J7/$K7),"") -> 209803.92 | Q7: =IFERROR(IF(OR($J7="",$H7="",$I7=""),"",$J7/($H7*$I7)*1000),"") -> 9067.7966 | R7: Aktif | S7: 2026-02-02 | T7: Nuri | V7: =IF($J7="","",RANK($J7,$J$6:$J$105,0)+COUNTIF($J$6:$J7,$J7)-1) -> 2 | W7: =IF($O7="","",RANK($O7,$O$6:$O$105,0)+COUNTIF($O$6:$O7,$O7)-1) -> 3
A8: =IF($B8="","",ROW()-5) -> 3 | B8: Dimas Nugroho | C8: @dimasnugroho | D8: Instagram | E8: instagram.com/dimasnugroho | F8: 132000 | G8: =IF($F8="","",LOOKUP($F8,Referensi!$A$6:$A$10,Referensi!$B$6:$B$10)) -> Mid | H8: 31000 | I8: 8 | J8: 4900000 | K8: 22 | L8: 0.15 | M8: =IF(OR($J8="",$L8=""),"",$J8*$L8) -> 735000 | N8: =IF($J8="","",$J8-$M8) -> 4165000 | O8: =IFERROR(IF(OR($J8="",$F8=""),"",$J8/$F8*1000),"") -> 37121.212 | P8: =IFERROR(IF(OR($J8="",$K8=""),"",$J8/$K8),"") -> 222727.27 | Q8: =IFERROR(IF(OR($J8="",$H8="",$I8=""),"",$J8/($H8*$I8)*1000),"") -> 19758.065 | R8: Pantau | S8: 2026-01-20 | T8: Nuri | U8: Followers besar, penjualan kecil | V8: =IF($J8="","",RANK($J8,$J$6:$J$105,0)+COUNTIF($J$6:$J8,$J8)-1) -> 4 | W8: =IF($O8="","",RANK($O8,$O$6:$O$105,0)+COUNTIF($O$6:$O8,$O8)-1) -> 5
A9: =IF($B9="","",ROW()-5) -> 4 | B9: Aditya Wijaya | C9: @adityawjy | D9: TikTok | E9: tiktok.com/@adityawjy | F9: 610000 | G9: =IF($F9="","",LOOKUP($F9,Referensi!$A$6:$A$10,Referensi!$B$6:$B$10)) -> Macro | H9: 240000 | I9: 10 | J9: 33500000 | K9: 158 | L9: 0.1 | M9: =IF(OR($J9="",$L9=""),"",$J9*$L9) -> 3350000 | N9: =IF($J9="","",$J9-$M9) -> 30150000 | O9: =IFERROR(IF(OR($J9="",$F9=""),"",$J9/$F9*1000),"") -> 54918.033 | P9: =IFERROR(IF(OR($J9="",$K9=""),"",$J9/$K9),"") -> 212025.32 | Q9: =IFERROR(IF(OR($J9="",$H9="",$I9=""),"",$J9/($H9*$I9)*1000),"") -> 13958.333 | R9: Aktif | S9: 2025-11-08 | T9: Nuri | V9: =IF($J9="","",RANK($J9,$J$6:$J$105,0)+COUNTIF($J$6:$J9,$J9)-1) -> 1 | W9: =IF($O9="","",RANK($O9,$O$6:$O$105,0)+COUNTIF($O$6:$O9,$O9)-1) -> 4
A10: =IF($B10="","",ROW()-5) -> 5 | B10: Fajar Ramadhan | C10: @fajarrmdhn | D10: Shopee Live | E10: shopee.co.id/fajarrmdhn | F10: 3200 | G10: =IF($F10="","",LOOKUP($F10,Referensi!$A$6:$A$10,Referensi!$B$6:$B$10)) -> Nano | H10: 11000 | I10: 24 | J10: 2150000 | K10: 13 | L10: 0.12 | M10: =IF(OR($J10="",$L10=""),"",$J10*$L10) -> 258000 | N10: =IF($J10="","",$J10-$M10) -> 1892000 | O10: =IFERROR(IF(OR($J10="",$F10=""),"",$J10/$F10*1000),"") -> 671875 | P10: =IFERROR(IF(OR($J10="",$K10=""),"",$J10/$K10),"") -> 165384.62 | Q10: =IFERROR(IF(OR($J10="",$H10="",$I10=""),"",$J10/($H10*$I10)*1000),"") -> 8143.9394 | R10: Baru | S10: 2026-06-30 | T10: Nuri | V10: =IF($J10="","",RANK($J10,$J$6:$J$105,0)+COUNTIF($J$6:$J10,$J10)-1) -> 5 | W10: =IF($O10="","",RANK($O10,$O$6:$O$105,0)+COUNTIF($O$6:$O10,$O10)-1) -> 2
A11: =IF($B11="","",ROW()-5) | G11: =IF($F11="","",LOOKUP($F11,Referensi!$A$6:$A$10,Referensi!$B$6:$B$10)) | M11: =IF(OR($J11="",$L11=""),"",$J11*$L11) | N11: =IF($J11="","",$J11-$M11) | O11: =IFERROR(IF(OR($J11="",$F11=""),"",$J11/$F11*1000),"") | P11: =IFERROR(IF(OR($J11="",$K11=""),"",$J11/$K11),"") | Q11: =IFERROR(IF(OR($J11="",$H11="",$I11=""),"",$J11/($H11*$I11)*1000),"") | V11: =IF($J11="","",RANK($J11,$J$6:$J$105,0)+COUNTIF($J$6:$J11,$J11)-1) | W11: =IF($O11="","",RANK($O11,$O$6:$O$105,0)+COUNTIF($O$6:$O11,$O11)-1)
A12: =IF($B12="","",ROW()-5) | G12: =IF($F12="","",LOOKUP($F12,Referensi!$A$6:$A$10,Referensi!$B$6:$B$10)) | M12: =IF(OR($J12="",$L12=""),"",$J12*$L12) | N12: =IF($J12="","",$J12-$M12) | O12: =IFERROR(IF(OR($J12="",$F12=""),"",$J12/$F12*1000),"") | P12: =IFERROR(IF(OR($J12="",$K12=""),"",$J12/$K12),"") | Q12: =IFERROR(IF(OR($J12="",$H12="",$I12=""),"",$J12/($H12*$I12)*1000),"") | V12: =IF($J12="","",RANK($J12,$J$6:$J$105,0)+COUNTIF($J$6:$J12,$J12)-1) | W12: =IF($O12="","",RANK($O12,$O$6:$O$105,0)+COUNTIF($O$6:$O12,$O12)-1)
A13: =IF($B13="","",ROW()-5) | G13: =IF($F13="","",LOOKUP($F13,Referensi!$A$6:$A$10,Referensi!$B$6:$B$10)) | M13: =IF(OR($J13="",$L13=""),"",$J13*$L13) | N13: =IF($J13="","",$J13-$M13) | O13: =IFERROR(IF(OR($J13="",$F13=""),"",$J13/$F13*1000),"") | P13: =IFERROR(IF(OR($J13="",$K13=""),"",$J13/$K13),"") | Q13: =IFERROR(IF(OR($J13="",$H13="",$I13=""),"",$J13/($H13*$I13)*1000),"") | V13: =IF($J13="","",RANK($J13,$J$6:$J$105,0)+COUNTIF($J$6:$J13,$J13)-1) | W13: =IF($O13="","",RANK($O13,$O$6:$O$105,0)+COUNTIF($O$6:$O13,$O13)-1)
A14: =IF($B14="","",ROW()-5) | G14: =IF($F14="","",LOOKUP($F14,Referensi!$A$6:$A$10,Referensi!$B$6:$B$10)) | M14: =IF(OR($J14="",$L14=""),"",$J14*$L14) | N14: =IF($J14="","",$J14-$M14) | O14: =IFERROR(IF(OR($J14="",$F14=""),"",$J14/$F14*1000),"") | P14: =IFERROR(IF(OR($J14="",$K14=""),"",$J14/$K14),"") | Q14: =IFERROR(IF(OR($J14="",$H14="",$I14=""),"",$J14/($H14*$I14)*1000),"") | V14: =IF($J14="","",RANK($J14,$J$6:$J$105,0)+COUNTIF($J$6:$J14,$J14)-1) | W14: =IF($O14="","",RANK($O14,$O$6:$O$105,0)+COUNTIF($O$6:$O14,$O14)-1)
A15: =IF($B15="","",ROW()-5) | G15: =IF($F15="","",LOOKUP($F15,Referensi!$A$6:$A$10,Referensi!$B$6:$B$10)) | M15: =IF(OR($J15="",$L15=""),"",$J15*$L15) | N15: =IF($J15="","",$J15-$M15) | O15: =IFERROR(IF(OR($J15="",$F15=""),"",$J15/$F15*1000),"") | P15: =IFERROR(IF(OR($J15="",$K15=""),"",$J15/$K15),"") | Q15: =IFERROR(IF(OR($J15="",$H15="",$I15=""),"",$J15/($H15*$I15)*1000),"") | V15: =IF($J15="","",RANK($J15,$J$6:$J$105,0)+COUNTIF($J$6:$J15,$J15)-1) | W15: =IF($O15="","",RANK($O15,$O$6:$O$105,0)+COUNTIF($O$6:$O15,$O15)-1)
A16: =IF($B16="","",ROW()-5) | G16: =IF($F16="","",LOOKUP($F16,Referensi!$A$6:$A$10,Referensi!$B$6:$B$10)) | M16: =IF(OR($J16="",$L16=""),"",$J16*$L16) | N16: =IF($J16="","",$J16-$M16) | O16: =IFERROR(IF(OR($J16="",$F16=""),"",$J16/$F16*1000),"") | P16: =IFERROR(IF(OR($J16="",$K16=""),"",$J16/$K16),"") | Q16: =IFERROR(IF(OR($J16="",$H16="",$I16=""),"",$J16/($H16*$I16)*1000),"") | V16: =IF($J16="","",RANK($J16,$J$6:$J$105,0)+COUNTIF($J$6:$J16,$J16)-1) | W16: =IF($O16="","",RANK($O16,$O$6:$O$105,0)+COUNTIF($O$6:$O16,$O16)-1)
A17: =IF($B17="","",ROW()-5) | G17: =IF($F17="","",LOOKUP($F17,Referensi!$A$6:$A$10,Referensi!$B$6:$B$10)) | M17: =IF(OR($J17="",$L17=""),"",$J17*$L17) | N17: =IF($J17="","",$J17-$M17) | O17: =IFERROR(IF(OR($J17="",$F17=""),"",$J17/$F17*1000),"") | P17: =IFERROR(IF(OR($J17="",$K17=""),"",$J17/$K17),"") | Q17: =IFERROR(IF(OR($J17="",$H17="",$I17=""),"",$J17/($H17*$I17)*1000),"") | V17: =IF($J17="","",RANK($J17,$J$6:$J$105,0)+COUNTIF($J$6:$J17,$J17)-1) | W17: =IF($O17="","",RANK($O17,$O$6:$O$105,0)+COUNTIF($O$6:$O17,$O17)-1)
A18: =IF($B18="","",ROW()-5) | G18: =IF($F18="","",LOOKUP($F18,Referensi!$A$6:$A$10,Referensi!$B$6:$B$10)) | M18: =IF(OR($J18="",$L18=""),"",$J18*$L18) | N18: =IF($J18="","",$J18-$M18) | O18: =IFERROR(IF(OR($J18="",$F18=""),"",$J18/$F18*1000),"") | P18: =IFERROR(IF(OR($J18="",$K18=""),"",$J18/$K18),"") | Q18: =IFERROR(IF(OR($J18="",$H18="",$I18=""),"",$J18/($H18*$I18)*1000),"") | V18: =IF($J18="","",RANK($J18,$J$6:$J$105,0)+COUNTIF($J$6:$J18,$J18)-1) | W18: =IF($O18="","",RANK($O18,$O$6:$O$105,0)+COUNTIF($O$6:$O18,$O18)-1)
A19: =IF($B19="","",ROW()-5) | G19: =IF($F19="","",LOOKUP($F19,Referensi!$A$6:$A$10,Referensi!$B$6:$B$10)) | M19: =IF(OR($J19="",$L19=""),"",$J19*$L19) | N19: =IF($J19="","",$J19-$M19) | O19: =IFERROR(IF(OR($J19="",$F19=""),"",$J19/$F19*1000),"") | P19: =IFERROR(IF(OR($J19="",$K19=""),"",$J19/$K19),"") | Q19: =IFERROR(IF(OR($J19="",$H19="",$I19=""),"",$J19/($H19*$I19)*1000),"") | V19: =IF($J19="","",RANK($J19,$J$6:$J$105,0)+COUNTIF($J$6:$J19,$J19)-1) | W19: =IF($O19="","",RANK($O19,$O$6:$O$105,0)+COUNTIF($O$6:$O19,$O19)-1)
A20: =IF($B20="","",ROW()-5) | G20: =IF($F20="","",LOOKUP($F20,Referensi!$A$6:$A$10,Referensi!$B$6:$B$10)) | M20: =IF(OR($J20="",$L20=""),"",$J20*$L20) | N20: =IF($J20="","",$J20-$M20) | O20: =IFERROR(IF(OR($J20="",$F20=""),"",$J20/$F20*1000),"") | P20: =IFERROR(IF(OR($J20="",$K20=""),"",$J20/$K20),"") | Q20: =IFERROR(IF(OR($J20="",$H20="",$I20=""),"",$J20/($H20*$I20)*1000),"") | V20: =IF($J20="","",RANK($J20,$J$6:$J$105,0)+COUNTIF($J$6:$J20,$J20)-1) | W20: =IF($O20="","",RANK($O20,$O$6:$O$105,0)+COUNTIF($O$6:$O20,$O20)-1)
A21: =IF($B21="","",ROW()-5) | G21: =IF($F21="","",LOOKUP($F21,Referensi!$A$6:$A$10,Referensi!$B$6:$B$10)) | M21: =IF(OR($J21="",$L21=""),"",$J21*$L21) | N21: =IF($J21="","",$J21-$M21) | O21: =IFERROR(IF(OR($J21="",$F21=""),"",$J21/$F21*1000),"") | P21: =IFERROR(IF(OR($J21="",$K21=""),"",$J21/$K21),"") | Q21: =IFERROR(IF(OR($J21="",$H21="",$I21=""),"",$J21/($H21*$I21)*1000),"") | V21: =IF($J21="","",RANK($J21,$J$6:$J$105,0)+COUNTIF($J$6:$J21,$J21)-1) | W21: =IF($O21="","",RANK($O21,$O$6:$O$105,0)+COUNTIF($O$6:$O21,$O21)-1)
A22: =IF($B22="","",ROW()-5) | G22: =IF($F22="","",LOOKUP($F22,Referensi!$A$6:$A$10,Referensi!$B$6:$B$10)) | M22: =IF(OR($J22="",$L22=""),"",$J22*$L22) | N22: =IF($J22="","",$J22-$M22) | O22: =IFERROR(IF(OR($J22="",$F22=""),"",$J22/$F22*1000),"") | P22: =IFERROR(IF(OR($J22="",$K22=""),"",$J22/$K22),"") | Q22: =IFERROR(IF(OR($J22="",$H22="",$I22=""),"",$J22/($H22*$I22)*1000),"") | V22: =IF($J22="","",RANK($J22,$J$6:$J$105,0)+COUNTIF($J$6:$J22,$J22)-1) | W22: =IF($O22="","",RANK($O22,$O$6:$O$105,0)+COUNTIF($O$6:$O22,$O22)-1)
... A105: =IF($B105="","",ROW()-5) | G105: =IF($F105="","",LOOKUP($F105,Referensi!$A$6:$A$10,Referensi!$B$6:$B$10)) | M105: =IF(OR($J105="",$L105=""),"",$J105*$L105) | N105: =IF($J105="","",$J105-$M105) | O105: =IFERROR(IF(OR($J105="",$F105=""),"",$J105/$F105*1000),"") | P105: =IFERROR(IF(OR($J105="",$K105=""),"",$J105/$K105),"") | Q105: =IFERROR(IF(OR($J105="",$H105="",$I105=""),"",$J105/($H105*$I105)*1000),"") | V105: =IF($J105="","",RANK($J105,$J$6:$J$105,0)+COUNTIF($J$6:$J105,$J105)-1) | W105: =IF($O105="","",RANK($O105,$O$6:$O$105,0)+COUNTIF($O$6:$O105,$O105)-1)
B107: TOTAL | F107: =SUM(F6:F105) -> 799700 | J107: =SUM(J6:J105) -> 68750000 | K107: =SUM(K6:K105) -> 329 | M107: =SUM(M6:M105) -> 7299000 | N107: =SUM(N6:N105) -> 61451000
B109: Baris 6 sampai 10 adalah CONTOH. Hapus isinya sebelum dipakai; rumusnya akan tetap jalan.

Sheet Rekap Bulanan
A1: REKAP GMV BULANAN
A2: Namanya ikut Daftar Affiliate. Isi GMV tiap bulan di kolom krem.
A4: No | B4: Nama Affiliate | C4: Jan | D4: Feb | E4: Mar | F4: Apr | G4: Mei | H4: Jun | I4: Jul | J4: Agu | K4: Sep | L4: Okt | M4: Nov | N4: Des | O4: Total Setahun | P4: Rata-rata per Bulan Aktif | Q4: Bulan Tertinggi
A6: =IF($B6="","",ROW()-5) -> 1 | B6: =IF('Daftar Affiliate'!B6="","",'Daftar Affiliate'!B6) -> Rizky Pratama | O6: =IF($B6="","",SUM($C6:$N6)) -> 0 | P6: =IFERROR(IF($B6="","",AVERAGEIF($C6:$N6,">0")),"") | Q6: =IFERROR(IF(SUM($C6:$N6)=0,"",INDEX($C$4:$N$4,MATCH(MAX($C6:$N6),$C6:$N6,0))),"")
A7: =IF($B7="","",ROW()-5) -> 2 | B7: =IF('Daftar Affiliate'!B7="","",'Daftar Affiliate'!B7) -> Bagas Adi | O7: =IF($B7="","",SUM($C7:$N7)) -> 0 | P7: =IFERROR(IF($B7="","",AVERAGEIF($C7:$N7,">0")),"") | Q7: =IFERROR(IF(SUM($C7:$N7)=0,"",INDEX($C$4:$N$4,MATCH(MAX($C7:$N7),$C7:$N7,0))),"")
A8: =IF($B8="","",ROW()-5) -> 3 | B8: =IF('Daftar Affiliate'!B8="","",'Daftar Affiliate'!B8) -> Dimas Nugroho | O8: =IF($B8="","",SUM($C8:$N8)) -> 0 | P8: =IFERROR(IF($B8="","",AVERAGEIF($C8:$N8,">0")),"") | Q8: =IFERROR(IF(SUM($C8:$N8)=0,"",INDEX($C$4:$N$4,MATCH(MAX($C8:$N8),$C8:$N8,0))),"")
A9: =IF($B9="","",ROW()-5) -> 4 | B9: =IF('Daftar Affiliate'!B9="","",'Daftar Affiliate'!B9) -> Aditya Wijaya | O9: =IF($B9="","",SUM($C9:$N9)) -> 0 | P9: =IFERROR(IF($B9="","",AVERAGEIF($C9:$N9,">0")),"") | Q9: =IFERROR(IF(SUM($C9:$N9)=0,"",INDEX($C$4:$N$4,MATCH(MAX($C9:$N9),$C9:$N9,0))),"")
A10: =IF($B10="","",ROW()-5) -> 5 | B10: =IF('Daftar Affiliate'!B10="","",'Daftar Affiliate'!B10) -> Fajar Ramadhan | O10: =IF($B10="","",SUM($C10:$N10)) -> 0 | P10: =IFERROR(IF($B10="","",AVERAGEIF($C10:$N10,">0")),"") | Q10: =IFERROR(IF(SUM($C10:$N10)=0,"",INDEX($C$4:$N$4,MATCH(MAX($C10:$N10),$C10:$N10,0))),"")
A11: =IF($B11="","",ROW()-5) | B11: =IF('Daftar Affiliate'!B11="","",'Daftar Affiliate'!B11) | O11: =IF($B11="","",SUM($C11:$N11)) | P11: =IFERROR(IF($B11="","",AVERAGEIF($C11:$N11,">0")),"") | Q11: =IFERROR(IF(SUM($C11:$N11)=0,"",INDEX($C$4:$N$4,MATCH(MAX($C11:$N11),$C11:$N11,0))),"")
A12: =IF($B12="","",ROW()-5) | B12: =IF('Daftar Affiliate'!B12="","",'Daftar Affiliate'!B12) | O12: =IF($B12="","",SUM($C12:$N12)) | P12: =IFERROR(IF($B12="","",AVERAGEIF($C12:$N12,">0")),"") | Q12: =IFERROR(IF(SUM($C12:$N12)=0,"",INDEX($C$4:$N$4,MATCH(MAX($C12:$N12),$C12:$N12,0))),"")
A13: =IF($B13="","",ROW()-5) | B13: =IF('Daftar Affiliate'!B13="","",'Daftar Affiliate'!B13) | O13: =IF($B13="","",SUM($C13:$N13)) | P13: =IFERROR(IF($B13="","",AVERAGEIF($C13:$N13,">0")),"") | Q13: =IFERROR(IF(SUM($C13:$N13)=0,"",INDEX($C$4:$N$4,MATCH(MAX($C13:$N13),$C13:$N13,0))),"")
A14: =IF($B14="","",ROW()-5) | B14: =IF('Daftar Affiliate'!B14="","",'Daftar Affiliate'!B14) | O14: =IF($B14="","",SUM($C14:$N14)) | P14: =IFERROR(IF($B14="","",AVERAGEIF($C14:$N14,">0")),"") | Q14: =IFERROR(IF(SUM($C14:$N14)=0,"",INDEX($C$4:$N$4,MATCH(MAX($C14:$N14),$C14:$N14,0))),"")
A15: =IF($B15="","",ROW()-5) | B15: =IF('Daftar Affiliate'!B15="","",'Daftar Affiliate'!B15) | O15: =IF($B15="","",SUM($C15:$N15)) | P15: =IFERROR(IF($B15="","",AVERAGEIF($C15:$N15,">0")),"") | Q15: =IFERROR(IF(SUM($C15:$N15)=0,"",INDEX($C$4:$N$4,MATCH(MAX($C15:$N15),$C15:$N15,0))),"")
A16: =IF($B16="","",ROW()-5) | B16: =IF('Daftar Affiliate'!B16="","",'Daftar Affiliate'!B16) | O16: =IF($B16="","",SUM($C16:$N16)) | P16: =IFERROR(IF($B16="","",AVERAGEIF($C16:$N16,">0")),"") | Q16: =IFERROR(IF(SUM($C16:$N16)=0,"",INDEX($C$4:$N$4,MATCH(MAX($C16:$N16),$C16:$N16,0))),"")
A17: =IF($B17="","",ROW()-5) | B17: =IF('Daftar Affiliate'!B17="","",'Daftar Affiliate'!B17) | O17: =IF($B17="","",SUM($C17:$N17)) | P17: =IFERROR(IF($B17="","",AVERAGEIF($C17:$N17,">0")),"") | Q17: =IFERROR(IF(SUM($C17:$N17)=0,"",INDEX($C$4:$N$4,MATCH(MAX($C17:$N17),$C17:$N17,0))),"")
... A105: =IF($B105="","",ROW()-5) | B105: =IF('Daftar Affiliate'!B105="","",'Daftar Affiliate'!B105) | O105: =IF($B105="","",SUM($C105:$N105)) | P105: =IFERROR(IF($B105="","",AVERAGEIF($C105:$N105,">0")),"") | Q105: =IFERROR(IF(SUM($C105:$N105)=0,"",INDEX($C$4:$N$4,MATCH(MAX($C105:$N105),$C105:$N105,0))),"")
B107: TOTAL | C107: =SUM(C6:C105) -> 0 | D107: =SUM(D6:D105) -> 0 | E107: =SUM(E6:E105) -> 0 | F107: =SUM(F6:F105) -> 0 | G107: =SUM(G6:G105) -> 0 | H107: =SUM(H6:H105) -> 0 | I107: =SUM(I6:I105) -> 0 | J107: =SUM(J6:J105) -> 0 | ... O107: =SUM(O6:O105) -> 0
